#VRML_SIM R2025a utf8

EXTERNPROTO "https://raw.githubusercontent.com/cyberbotics/webots/R2025a/projects/objects/backgrounds/protos/TexturedBackground.proto"
EXTERNPROTO "https://raw.githubusercontent.com/cyberbotics/webots/R2025a/projects/objects/backgrounds/protos/TexturedBackgroundLight.proto"
EXTERNPROTO "https://raw.githubusercontent.com/cyberbotics/webots/R2025a/projects/objects/floors/protos/Floor.proto"
EXTERNPROTO "https://raw.githubusercontent.com/cyberbotics/webots/R2025a/projects/appearances/protos/CorrugatedMetal.proto"
EXTERNPROTO "https://raw.githubusercontent.com/cyberbotics/webots/R2025a/projects/objects/apartment_structure/protos/Ceiling.proto"
EXTERNPROTO "https://raw.githubusercontent.com/cyberbotics/webots/R2025a/projects/objects/apartment_structure/protos/Door.proto"
EXTERNPROTO "https://raw.githubusercontent.com/cyberbotics/webots/R2025a/projects/objects/apartment_structure/protos/DoorLever.proto"
EXTERNPROTO "https://raw.githubusercontent.com/cyberbotics/webots/R2025a/projects/objects/factory/valves/protos/LeverValve.proto"
EXTERNPROTO "https://raw.githubusercontent.com/cyberbotics/webots/R2025a/projects/objects/factory/pipes/protos/PipeSection.proto"
EXTERNPROTO "https://raw.githubusercontent.com/cyberbotics/webots/R2025a/projects/objects/factory/pipes/protos/LJoint.proto"
EXTERNPROTO "https://raw.githubusercontent.com/cyberbotics/webots/R2025a/projects/objects/factory/pipes/protos/TJoint.proto"
EXTERNPROTO "https://raw.githubusercontent.com/cyberbotics/webots/R2025a/projects/objects/factory/pallet/protos/WoodenPalletStack.proto"
EXTERNPROTO "../protos/WoodenBox.proto"
EXTERNPROTO "../protos/QRBox.proto"
EXTERNPROTO "https://raw.githubusercontent.com/cyberbotics/webots/R2025a/projects/appearances/protos/OsbWood.proto"
EXTERNPROTO "https://raw.githubusercontent.com/cyberbotics/webots/R2025a/projects/appearances/protos/BrushedAluminium.proto"
EXTERNPROTO "https://raw.githubusercontent.com/cyberbotics/webots/R2025a/projects/objects/floors/protos/RectangleArena.proto"
EXTERNPROTO "https://raw.githubusercontent.com/cyberbotics/webots/R2025a/projects/appearances/protos/Parquetry.proto"
EXTERNPROTO "https://raw.githubusercontent.com/cyberbotics/webots/R2025a/projects/objects/factory/containers/protos/MetalStorageBox.proto"
EXTERNPROTO "https://raw.githubusercontent.com/cyberbotics/webots/R2025a/projects/devices/robotiq/protos/Robotiq2f140Gripper.proto"
EXTERNPROTO "https://raw.githubusercontent.com/cyberbotics/webots/R2025a/projects/appearances/protos/OldSteel.proto"
EXTERNPROTO "https://raw.githubusercontent.com/cyberbotics/webots/R2025a/projects/appearances/protos/ScrewThread.proto"

WorldInfo {
  title "Pick and Place"
  window "pick_and_place"
  basicTimeStep 16
  defaultDamping Damping {
  }
  contactProperties [
    ContactProperties {
      material2 "box"
      coulombFriction [
        10
      ]
    }
  ]
}
Viewpoint {
  orientation 0.2753115230992346 -0.26023675932618184 -0.9254622598162426 4.579002555718584
  position 1.900892280243032 -3.0042088311361868 3.4971830575883605
  exposure 1.5
}
TexturedBackground {
  texture "factory"
}
TexturedBackgroundLight {
  texture "factory"
  castShadows FALSE
}
SpotLight {
  attenuation 0 0 1
  beamWidth 0.7
  intensity 10
  location 0 0 4
  castShadows TRUE
}
Floor {
  rotation 0 0 1 -1.5707963267948966
  size 12 12
  tileSize 1 1
  appearance PBRAppearance {
    baseColorMap ImageTexture {
      url [
        "../textures/concrete.jpg"
      ]
    }
    roughness 1
    metalness 0
  }
}
MetalStorageBox {
  translation 0.430001 1.85 0
  rotation 0 0 1 1.5708
}
RectangleArena {
  translation -0.43 0.93 0.01
  floorAppearance Parquetry {
    type "dark strip"
    colorOverride 0 0 1
  }
}
QRBox {
  hidden linearVelocity_0 -0.012213333182217638 0.014023627775545153 -1.1666505111142947e-08
  hidden angularVelocity_0 -3.462848643648846e-07 5.209882081625731e-07 1.4946538079917675
  translation 0.4228520376068923 0.5235671513565838 0.16516306404140227
  rotation -0.795702223281061 -0.6056880150317794 1.7675956037843116e-05 3.141590776660645
  name "C"
  color 1 0.6 0
  qrTexture [
    "../textures/qr2.png"
  ]
}
QRBox {
  translation 1.1133196172209132 0.8698651194941477 0.16997547500000004
  rotation -0.05938967739274556 0.705858649525238 0.705858649525238 -3.0229526542327343
  name "B"
  color 1 0.6 0
  qrTexture [
    "../textures/qr1.png"
  ]
}
DEF WALL Solid {
  translation 0 6 2.5
  rotation 1 0 0 1.5708
  children [
    DEF WALL_SHAPE Shape {
      appearance CorrugatedMetal {
        textureTransform TextureTransform {
          scale 2 2
        }
      }
      geometry Plane {
        size 12 5
      }
      castShadows FALSE
    }
  ]
  boundingObject USE WALL_SHAPE
}
DEF WALL Solid {
  translation 6 0 2.5
  rotation -0.5773509358508296 0.5773469358512743 0.5773529358506075 -2.094395307179586
  children [
    USE WALL_SHAPE
  ]
  name "solid(1)"
  boundingObject USE WALL_SHAPE
}
DEF WALL Solid {
  translation 0 -6 2.5
  rotation 3.808301514364728e-06 0.7071082811804253 0.7071052811792324 3.14159
  children [
    USE WALL_SHAPE
  ]
  name "solid(2)"
  boundingObject USE WALL_SHAPE
}
DEF WALL Solid {
  translation -6 0 2.5
  rotation -0.5773509358554485 -0.5773489358556708 -0.5773509358554485 -2.094395307179586
  children [
    USE WALL_SHAPE
  ]
  name "solid(3)"
  boundingObject USE WALL_SHAPE
}
Ceiling {
  translation 0 0 5
  size 12 12
  castShadows FALSE
}
Door {
  translation -2.45 5.96 0
  rotation 0 0 -1 1.5708
  size 0.01 1.2 2
  canBeOpen FALSE
  doorHandle DoorLever {
    translation 0 0 0.045
    mass 0
    hasStaticParent TRUE
    castShadows FALSE
  }
  castShadows FALSE
}
DEF PIPES Pose {
  rotation 0 0 1 -1.57
  children [
    LeverValve {
      hidden position_0_0 -1.1299103803312982e-06
      hidden translation_1 0 6.700475582343995e-08 -1.122227311078916e-13
      hidden rotation_1 -1 0 0 3.3502105440931777e-06
      translation 0.50999991 -5.83 1
      rotation 0 0 1 1.5708
      scale 1 1 1
    }
    PipeSection {
      translation 2.11 -5.86 0.96000003
      rotation 0.7071067811860158 0 0.7071067811860158 -3.1415853071795863
      height 3
      radius 0.07
    }
    PipeSection {
      translation -2.81 -5.86 0.9600001
      rotation 0.7071067811860158 0 0.7071067811860158 -3.1415853071795863
      name "pipe section(1)"
      height 6.4
      radius 0.07
    }
    PipeSection {
      translation -4.39 -5.87 3.83
      rotation 0.7071067811860158 0 0.7071067811860158 -3.1415853071795863
      name "pipe section(2)"
      height 3.3
      radius 0.07
    }
    PipeSection {
      translation -1.63 -5.86 0.65
      rotation 0.7071067811860158 0 0.7071067811860158 -3.1415853071795863
      name "pipe section(3)"
      height 8.8
      radius 0.07
    }
    PipeSection {
      translation 3.857 -5.86 0.34
      rotation 0 0 -1 -1.5707953071795862
      name "pipe section(4)"
      height 0.7
      radius 0.07
    }
    PipeSection {
      translation 3.037 -5.86 0.19
      rotation 0 0 -1 -1.5707953071795862
      name "pipe section(5)"
      height 0.4
      radius 0.07
    }
    PipeSection {
      translation -2.443 -5.84 2.37
      rotation 0 0 -1 -1.5707953071795862
      name "pipe section(6)"
      height 2.4
      radius 0.07
    }
    LJoint {
      translation 3.74 -5.8610001 0.85599996
      rotation 0 1 0 3.14159
      scale 2.4 2.4 2.4
    }
    LJoint {
      translation 2.93 -5.8610001 0.54599994
      rotation 0 1 0 3.14159
      name "L joint pipe(1)"
      scale 2.4 2.4 2.4
    }
    LJoint {
      translation -2.55 -5.845 3.7259999
      rotation 0 1 0 3.14159
      name "L joint pipe(2)"
      scale 2.4 2.4 2.4
    }
    TJoint {
      translation -2.44 -5.843 1.0259999
      rotation 0 1 0 3.14159
      scale 2.4 2.4 2.4
    }
  ]
}
WoodenPalletStack {
  translation 3.51824 5.0701 0.0986936
  rotation 0 0 1 -0.523595307179586
}
WoodenPalletStack {
  translation 5.0506856 4.3236115 0
  rotation 0 0 -1 1.0472
  name "wooden pallet stack(1)"
  palletNumber 2
}
WoodenBox {
  translation 5.0461957 -2.6920662 0.3
  rotation 0 0 1 -1.5707963267948966
}
WoodenBox {
  translation 5.0297142 -3.3127088 0.3
  rotation 0 0 1 -1.5707963267948966
  name "wooden box(1)"
}
WoodenBox {
  translation 5.0890438 -2.0668732 0.3
  rotation 0 0 -1 1.571421196638078
  name "wooden box(2)"
}
WoodenBox {
  translation 5.0324568 -3.0679729 0.9
  rotation 0.004999875004687304 0.004999875004687304 -0.9999750009374608 1.570821326586566
  name "wooden box(3)"
}
Robot {
  translation 0.467839 1.09956 2.51409e-06
  rotation -1.0934e-06 -6.94581e-07 1 3.14158
  children [
    Pose {
      translation -0.0467 0.047 0.0252
      rotation 1 0 0 -3.1415923071795864
      children [
        Camera {
          translation 0.0980466 -0.75717 -0.139999
          rotation 0.7071087811827946 0.7071047811840324 -9.297607122824011e-07 3.14159
          name "side_camera"
          fieldOfView 1
          width 1280
          height 720
          far 100
          recognition Recognition {
          }
        }
        Camera {
          translation -0.505984 -0.0423492 -0.674411
          rotation -0.5363409424393568 0.603555935225777 -0.5899649366843764 -2.200135307179586
          name "top_camera"
          fieldOfView 1
          width 1280
          height 720
          far 100
          recognition Recognition {
          }
        }
        DEF SCREW Group {
          children [
            Transform {
              scale 1.1 1.1 1.1
              children [
                Shape {
                  appearance OldSteel {
                  }
                  geometry Mesh {
                    url [
                      "https://raw.githubusercontent.com/cyberbotics/webots/R2025a/projects/robots/universal_robots/protos/UR5e/meshes/screw.obj"
                    ]
                  }
                }
              ]
            }
            DEF CYLINDER Pose {
              translation 0 0 0.02
              children [
                Shape {
                  appearance ScrewThread {
                    textureTransform TextureTransform {
                      rotation 1.5708
                      scale 1.6 2
                    }
                  }
                  geometry Cylinder {
                    height 0.04
                    radius 0.0044
                  }
                }
              ]
            }
          ]
        }
      ]
    }
    Pose {
      translation -0.0467 -0.047 0.0252
      rotation 1 0 0 -3.1415923071795864
      children [
        USE SCREW
      ]
    }
    Pose {
      translation 0.0464 -0.047 0.0252
      rotation 1 0 0 -3.1415923071795864
      children [
        USE SCREW
      ]
    }
    Pose {
      translation 0.0464 0.047 0.0252
      rotation 1 0 0 -3.1415923071795864
      children [
        USE SCREW
      ]
    }
    Shape {
      appearance DEF METAL_APPEARANCE PBRAppearance {
        baseColor 0.6 0.6 0.6
        roughness 0.7
      }
      geometry Mesh {
        url [
          "https://raw.githubusercontent.com/cyberbotics/webots/R2025a/projects/robots/universal_robots/protos/UR5e/meshes/base_link_0.obj"
        ]
      }
    }
    Shape {
      appearance DEF JOINT_APPEARANCE PBRAppearance {
        baseColor 0 0 0
        roughness 1
        metalness 0
      }
      geometry Mesh {
        url [
          "https://raw.githubusercontent.com/cyberbotics/webots/R2025a/projects/robots/universal_robots/protos/UR5e/meshes/base_link_1.obj"
        ]
      }
    }
    HingeJoint {
      jointParameters HingeJointParameters {
        position 4.462797205474284e-05
        axis 0 0 1
        anchor 0 0 0.163
      }
      device [
        RotationalMotor {
          name "shoulder_pan_joint"
          maxVelocity 3.14
          minPosition -6.28318530718
          maxPosition 6.28318530718
          maxTorque 150
        }
        PositionSensor {
          name "shoulder_pan_joint_sensor"
        }
      ]
      endPoint Solid {
        translation 5.272243786681788e-05 -9.885669774296115e-06 0.16271
        rotation 0.028859586337055244 0.03099611060312527 -0.999102780200282 0.0017696155337692018
        children [
          Shape {
            appearance USE METAL_APPEARANCE
            geometry Mesh {
              url [
                "https://raw.githubusercontent.com/cyberbotics/webots/R2025a/projects/robots/universal_robots/protos/UR5e/meshes/shoulder_link_0.obj"
              ]
            }
          }
          Shape {
            appearance USE JOINT_APPEARANCE
            geometry Mesh {
              url [
                "https://raw.githubusercontent.com/cyberbotics/webots/R2025a/projects/robots/universal_robots/protos/UR5e/meshes/shoulder_link_1.obj"
              ]
            }
          }
          Shape {
            appearance PBRAppearance {
              baseColor 0.4902 0.678431 0.8
              roughness 0.4
              metalness 0
              normalMap ImageTexture {
                url [
                  "https://raw.githubusercontent.com/cyberbotics/webots/R2025a/projects/robots/universal_robots/protos/UR5e/textures/normal_0.jpg"
                ]
              }
              occlusionMap ImageTexture {
                url [
                  "https://raw.githubusercontent.com/cyberbotics/webots/R2025a/projects/robots/universal_robots/protos/UR5e/textures/occlusion_0.jpg"
                ]
              }
            }
            geometry Mesh {
              url [
                "https://raw.githubusercontent.com/cyberbotics/webots/R2025a/projects/robots/universal_robots/protos/UR5e/meshes/shoulder_link_2.obj"
              ]
            }
          }
          Shape {
            appearance DEF SCREW_APPEARANCE PBRAppearance {
            }
            geometry Mesh {
              url [
                "https://raw.githubusercontent.com/cyberbotics/webots/R2025a/projects/robots/universal_robots/protos/UR5e/meshes/shoulder_link_3.obj"
              ]
            }
          }
          HingeJoint {
            jointParameters HingeJointParameters {
              position 0.00021441998263508396
              axis 0 1 0
              anchor 0 0.138 0
            }
            device [
              RotationalMotor {
                name "shoulder_lift_joint"
                maxVelocity 3.14
                minPosition -6.28318530718
                maxPosition 6.28318530718
                maxTorque 150
              }
              PositionSensor {
                name "shoulder_lift_joint_sensor"
              }
            ]
            endPoint Solid {
              translation 2.6447391157683223e-07 0.13799522842991624 -6.769785197301903e-05
              rotation 8.459901039099187e-05 -0.9999999894307752 -0.00011824321069192662 0.06980937793455869
              children [
                Shape {
                  appearance PBRAppearance {
                    baseColor 0.4902 0.678431 0.8
                    roughness 0.4
                    metalness 0
                    normalMap ImageTexture {
                      url [
                        "https://raw.githubusercontent.com/cyberbotics/webots/R2025a/projects/robots/universal_robots/protos/UR5e/textures/normal_1.jpg"
                      ]
                    }
                    occlusionMap ImageTexture {
                      url [
                        "https://raw.githubusercontent.com/cyberbotics/webots/R2025a/projects/robots/universal_robots/protos/UR5e/textures/occlusion_1.jpg"
                      ]
                    }
                  }
                  geometry Mesh {
                    url [
                      "https://raw.githubusercontent.com/cyberbotics/webots/R2025a/projects/robots/universal_robots/protos/UR5e/meshes/upper_arm_link_0.obj"
                    ]
                  }
                }
                Shape {
                  appearance USE SCREW_APPEARANCE
                  geometry Mesh {
                    url [
                      "https://raw.githubusercontent.com/cyberbotics/webots/R2025a/projects/robots/universal_robots/protos/UR5e/meshes/upper_arm_link_1.obj"
                    ]
                  }
                }
                Shape {
                  appearance USE METAL_APPEARANCE
                  geometry Mesh {
                    url [
                      "https://raw.githubusercontent.com/cyberbotics/webots/R2025a/projects/robots/universal_robots/protos/UR5e/meshes/upper_arm_link_2.obj"
                    ]
                  }
                }
                Shape {
                  appearance USE JOINT_APPEARANCE
                  geometry Mesh {
                    url [
                      "https://raw.githubusercontent.com/cyberbotics/webots/R2025a/projects/robots/universal_robots/protos/UR5e/meshes/upper_arm_link_3.obj"
                    ]
                  }
                }
                Shape {
                  appearance PBRAppearance {
                    baseColor 0.4902 0.678431 0.8
                    roughness 0.4
                    metalness 0
                    normalMap ImageTexture {
                      url [
                        "https://raw.githubusercontent.com/cyberbotics/webots/R2025a/projects/robots/universal_robots/protos/UR5e/textures/normal_2.jpg"
                      ]
                    }
                    occlusionMap ImageTexture {
                      url [
                        "https://raw.githubusercontent.com/cyberbotics/webots/R2025a/projects/robots/universal_robots/protos/UR5e/textures/occlusion_2.jpg"
                      ]
                    }
                  }
                  geometry Mesh {
                    url [
                      "https://raw.githubusercontent.com/cyberbotics/webots/R2025a/projects/robots/universal_robots/protos/UR5e/meshes/upper_arm_link_4.obj"
                    ]
                  }
                }
                Shape {
                  appearance USE SCREW_APPEARANCE
                  geometry Mesh {
                    url [
                      "https://raw.githubusercontent.com/cyberbotics/webots/R2025a/projects/robots/universal_robots/protos/UR5e/meshes/upper_arm_link_5.obj"
                    ]
                  }
                }
                Shape {
                  appearance DEF METAL_APPEARANCE_LIGHT PBRAppearance {
                    roughness 0.7
                  }
                  geometry Mesh {
                    url [
                      "https://raw.githubusercontent.com/cyberbotics/webots/R2025a/projects/robots/universal_robots/protos/UR5e/meshes/upper_arm_link_6.obj"
                    ]
                  }
                }
                Shape {
                  appearance USE JOINT_APPEARANCE
                  geometry Mesh {
                    url [
                      "https://raw.githubusercontent.com/cyberbotics/webots/R2025a/projects/robots/universal_robots/protos/UR5e/meshes/upper_arm_link_7.obj"
                    ]
                  }
                }
                Shape {
                  appearance USE METAL_APPEARANCE
                  geometry Mesh {
                    url [
                      "https://raw.githubusercontent.com/cyberbotics/webots/R2025a/projects/robots/universal_robots/protos/UR5e/meshes/upper_arm_link_8.obj"
                    ]
                  }
                }
                Shape {
                  appearance USE JOINT_APPEARANCE
                  geometry Mesh {
                    url [
                      "https://raw.githubusercontent.com/cyberbotics/webots/R2025a/projects/robots/universal_robots/protos/UR5e/meshes/upper_arm_link_9.obj"
                    ]
                  }
                }
                HingeJoint {
                  jointParameters HingeJointParameters {
                    position -0.00013580141225943472
                    axis 0 1 0
                    anchor 0 -0.131 0.425
                  }
                  device [
                    RotationalMotor {
                      name "elbow_joint"
                      maxVelocity 3.14
                      minPosition -3.14159265359
                      maxPosition 3.14159265359
                      maxTorque 150
                    }
                    PositionSensor {
                      name "elbow_joint_sensor"
                    }
                  ]
                  endPoint Solid {
                    translation -0.00025079195311876825 -0.13100531020167072 0.4213307774033076
                    rotation 4.1939884445728314e-06 -0.9999999998898854 1.423515553677692e-05 0.5226324524704713
                    children [
                      Shape {
                        appearance USE METAL_APPEARANCE
                        geometry Mesh {
                          url [
                            "https://raw.githubusercontent.com/cyberbotics/webots/R2025a/projects/robots/universal_robots/protos/UR5e/meshes/forearm_link_0.obj"
                          ]
                        }
                      }
                      Shape {
                        appearance USE METAL_APPEARANCE
                        geometry Mesh {
                          url [
                            "https://raw.githubusercontent.com/cyberbotics/webots/R2025a/projects/robots/universal_robots/protos/UR5e/meshes/forearm_link_1.obj"
                          ]
                        }
                      }
                      Shape {
                        appearance USE JOINT_APPEARANCE
                        geometry Mesh {
                          url [
                            "https://raw.githubusercontent.com/cyberbotics/webots/R2025a/projects/robots/universal_robots/protos/UR5e/meshes/forearm_link_2.obj"
                          ]
                        }
                      }
                      Shape {
                        appearance USE METAL_APPEARANCE_LIGHT
                        geometry Mesh {
                          url [
                            "https://raw.githubusercontent.com/cyberbotics/webots/R2025a/projects/robots/universal_robots/protos/UR5e/meshes/forearm_link_3.obj"
                          ]
                        }
                      }
                      Shape {
                        appearance USE JOINT_APPEARANCE
                        geometry Mesh {
                          url [
                            "https://raw.githubusercontent.com/cyberbotics/webots/R2025a/projects/robots/universal_robots/protos/UR5e/meshes/forearm_link_4.obj"
                          ]
                        }
                      }
                      Shape {
                        appearance PBRAppearance {
                          baseColor 0.4902 0.678431 0.8
                          roughness 0.4
                          metalness 0
                          normalMap ImageTexture {
                            url [
                              "https://raw.githubusercontent.com/cyberbotics/webots/R2025a/projects/robots/universal_robots/protos/UR5e/textures/normal_3.jpg"
                            ]
                          }
                          occlusionMap ImageTexture {
                            url [
                              "https://raw.githubusercontent.com/cyberbotics/webots/R2025a/projects/robots/universal_robots/protos/UR5e/textures/occlusion_3.jpg"
                            ]
                          }
                        }
                        geometry Mesh {
                          url [
                            "https://raw.githubusercontent.com/cyberbotics/webots/R2025a/projects/robots/universal_robots/protos/UR5e/meshes/forearm_link_5.obj"
                          ]
                        }
                      }
                      Shape {
                        appearance USE SCREW_APPEARANCE
                        geometry Mesh {
                          url [
                            "https://raw.githubusercontent.com/cyberbotics/webots/R2025a/projects/robots/universal_robots/protos/UR5e/meshes/forearm_link_6.obj"
                          ]
                        }
                      }
                      Shape {
                        appearance USE JOINT_APPEARANCE
                        geometry Mesh {
                          url [
                            "https://raw.githubusercontent.com/cyberbotics/webots/R2025a/projects/robots/universal_robots/protos/UR5e/meshes/forearm_link_7.obj"
                          ]
                        }
                      }
                      HingeJoint {
                        jointParameters HingeJointParameters {
                          position -1.9570024676672537e-05
                          axis 0 1 0
                          anchor 0 0 0.392
                        }
                        device [
                          RotationalMotor {
                            name "wrist_1_joint"
                            maxVelocity 6.28
                            minPosition -6.28318530718
                            maxPosition 6.28318530718
                            maxTorque 28
                          }
                          PositionSensor {
                            name "wrist_1_joint_sensor"
                          }
                        ]
                        endPoint Solid {
                          translation 0 0 0.392
                          rotation -0.5648643574051312 0.58349304092594 0.5834930410247303 2.113220238258025
                          children [
                            Shape {
                              appearance USE METAL_APPEARANCE
                              geometry Mesh {
                                url [
                                  "https://raw.githubusercontent.com/cyberbotics/webots/R2025a/projects/robots/universal_robots/protos/UR5e/meshes/wrist_1_link_0.obj"
                                ]
                              }
                            }
                            Shape {
                              appearance PBRAppearance {
                                baseColor 0.4902 0.678431 0.8
                                roughness 0.4
                                metalness 0
                                normalMap ImageTexture {
                                  url [
                                    "https://raw.githubusercontent.com/cyberbotics/webots/R2025a/projects/robots/universal_robots/protos/UR5e/textures/normal_4.jpg"
                                  ]
                                }
                                occlusionMap ImageTexture {
                                  url [
                                    "https://raw.githubusercontent.com/cyberbotics/webots/R2025a/projects/robots/universal_robots/protos/UR5e/textures/occlusion_4.jpg"
                                  ]
                                }
                              }
                              geometry Mesh {
                                url [
                                  "https://raw.githubusercontent.com/cyberbotics/webots/R2025a/projects/robots/universal_robots/protos/UR5e/meshes/wrist_1_link_1.obj"
                                ]
                              }
                            }
                            Shape {
                              appearance USE SCREW_APPEARANCE
                              geometry Mesh {
                                url [
                                  "https://raw.githubusercontent.com/cyberbotics/webots/R2025a/projects/robots/universal_robots/protos/UR5e/meshes/wrist_1_link_2.obj"
                                ]
                              }
                            }
                            Shape {
                              appearance USE JOINT_APPEARANCE
                              geometry Mesh {
                                url [
                                  "https://raw.githubusercontent.com/cyberbotics/webots/R2025a/projects/robots/universal_robots/protos/UR5e/meshes/wrist_1_link_3.obj"
                                ]
                              }
                            }
                            HingeJoint {
                              jointParameters HingeJointParameters {
                                position -2.9668491691499396e-05
                                axis 0 0 1
                                anchor 0 0.127 0
                              }
                              device [
                                RotationalMotor {
                                  name "wrist_2_joint"
                                  maxVelocity 6.28
                                  minPosition -6.28318530718
                                  maxPosition 6.28318530718
                                  maxTorque 28
                                }
                                PositionSensor {
                                  name "wrist_2_joint_sensor"
                                }
                              ]
                              endPoint Solid {
                                translation -0.009999999999136625 0.12700013140142288 6.728469999999851e-13
                                rotation 0.05665812745190245 -6.327432504610863e-07 -0.9983936380973407 6.122516317105173e-05
                                children [
                                  Shape {
                                    appearance USE METAL_APPEARANCE
                                    geometry Mesh {
                                      url [
                                        "https://raw.githubusercontent.com/cyberbotics/webots/R2025a/projects/robots/universal_robots/protos/UR5e/meshes/wrist_2_link_0.obj"
                                      ]
                                    }
                                  }
                                  Shape {
                                    appearance PBRAppearance {
                                      baseColor 0.4902 0.678431 0.8
                                      roughness 0.4
                                      metalness 0
                                      normalMap ImageTexture {
                                        url [
                                          "https://raw.githubusercontent.com/cyberbotics/webots/R2025a/projects/robots/universal_robots/protos/UR5e/textures/normal_5.jpg"
                                        ]
                                      }
                                      occlusionMap ImageTexture {
                                        url [
                                          "https://raw.githubusercontent.com/cyberbotics/webots/R2025a/projects/robots/universal_robots/protos/UR5e/textures/occlusion_5.jpg"
                                        ]
                                      }
                                    }
                                    geometry Mesh {
                                      url [
                                        "https://raw.githubusercontent.com/cyberbotics/webots/R2025a/projects/robots/universal_robots/protos/UR5e/meshes/wrist_2_link_1.obj"
                                      ]
                                    }
                                  }
                                  Shape {
                                    appearance USE SCREW_APPEARANCE
                                    geometry Mesh {
                                      url [
                                        "https://raw.githubusercontent.com/cyberbotics/webots/R2025a/projects/robots/universal_robots/protos/UR5e/meshes/wrist_2_link_2.obj"
                                      ]
                                    }
                                  }
                                  Shape {
                                    appearance USE JOINT_APPEARANCE
                                    geometry Mesh {
                                      url [
                                        "https://raw.githubusercontent.com/cyberbotics/webots/R2025a/projects/robots/universal_robots/protos/UR5e/meshes/wrist_2_link_3.obj"
                                      ]
                                    }
                                  }
                                  HingeJoint {
                                    jointParameters HingeJointParameters {
                                      position 1.1647774354506117e-05
                                      axis 0 1 0
                                      anchor 0 0 0.1
                                    }
                                    device [
                                      RotationalMotor {
                                        name "wrist_3_joint"
                                        maxVelocity 6.28
                                        minPosition -6.28318530718
                                        maxPosition 6.28318530718
                                        maxTorque 28
                                      }
                                      PositionSensor {
                                        name "wrist_3_joint_sensor"
                                      }
                                    ]
                                    endPoint Solid {
                                      translation 5.5219290767303695e-05 -0.008003938601048258 0.14244014331003338
                                      rotation -0.4086810687009887 -0.9103591582796853 0.06500759203139782 0.00011409616635893584
                                      children [
                                        Shape {
                                          appearance USE METAL_APPEARANCE
                                          geometry Mesh {
                                            url [
                                              "https://raw.githubusercontent.com/cyberbotics/webots/R2025a/projects/robots/universal_robots/protos/UR5e/meshes/wrist_3_link_0.obj"
                                            ]
                                          }
                                        }
                                        Pose {
                                          translation 0 0.1 0
                                          children [
                                            Robotiq2f140Gripper {
                                              hidden position_0_0 0.015177949639094305
                                              hidden position_0_1 -0.022106949478127
                                              hidden position_0_2 5.804873809228367e-05
                                              hidden position_0_3 0.004362252950349411
                                              hidden rotation_1 0.9999999999999999 0 0 1.874560574999628
                                              hidden position_2_0 0.0315322588640186
                                              hidden rotation_3 -1 0 0 0.6934677411359205
                                              hidden rotation_5 1 0 0 1.8644003050876663
                                              hidden position_5_0 0.03846134406410423
                                              hidden rotation_6 -2.6507392013592817e-08 0.8383524069245439 0.5451286470218049 3.14159299591926
                                              hidden position_7_0 0.017127257950029617
                                              hidden translation_8 0 0.08175534252841204 -0.028219997066642053
                                              hidden rotation_8 -1 0 0 0.707872742049911
                                              hidden rotation_10 -2.6057204928753867e-08 -0.8397829807265661 -0.542922227655125 3.141592996057484
                                              hidden position_10_0 0.012706827562168848
                                              rotation -1 0 0 1.5708
                                            }
                                          ]
                                        }
                                      ]
                                      name "wrist_3_link"
                                      boundingObject Group {
                                        children [
                                          Pose {
                                            translation 0 0.07 0
                                            rotation 1 0 0 -1.57079632679
                                            children [
                                              Cylinder {
                                                height 0.048
                                                radius 0.038
                                              }
                                            ]
                                          }
                                          Pose {
                                            translation 0 0.09 0
                                            rotation 1 0 0 -1.57079632679
                                            children [
                                              Cylinder {
                                                height 0.018
                                                radius 0.032
                                              }
                                            ]
                                          }
                                        ]
                                      }
                                      physics Physics {
                                        density -1
                                        mass 0.365
                                        centerOfMass [
                                          0 0.071 0
                                        ]
                                      }
                                      linearVelocity 2.6836750376596598e-05 8.002549570650332e-05 5.256532945442576e-07
                                      angularVelocity 1.1909040552557593e-05 -1.0746479045540195e-05 0.00017762225350161873
                                    }
                                  }
                                ]
                                name "wrist_2_link"
                                boundingObject Group {
                                  children [
                                    Pose {
                                      translation 0 -0.001 0.0995
                                      rotation 1 0 0 -1.57079632679
                                      children [
                                        Cylinder {
                                          height 0.108
                                          radius 0.04
                                        }
                                      ]
                                    }
                                    Pose {
                                      translation 0 -0.001 0.0676
                                      children [
                                        Cylinder {
                                          height 0.043
                                          radius 0.038
                                        }
                                      ]
                                    }
                                  ]
                                }
                                physics Physics {
                                  density -1
                                  mass 1.3
                                  centerOfMass [
                                    0 0 0.1
                                  ]
                                }
                                linearVelocity 1.8735063500406508e-05 6.430802185107296e-05 1.1208772170778577e-07
                                angularVelocity 6.472979049146203e-07 -1.0728368019039454e-05 0.0001847045246355189
                              }
                            }
                          ]
                          name "wrist_1_link"
                          boundingObject Group {
                            children [
                              Pose {
                                translation 0 0.089 0
                                rotation 1 0 0 -1.57079632679
                                children [
                                  Cylinder {
                                    height 0.086
                                    radius 0.038
                                  }
                                ]
                              }
                              Pose {
                                translation 0 0.126 0
                                children [
                                  Cylinder {
                                    height 0.112
                                    radius 0.038
                                  }
                                ]
                              }
                            ]
                          }
                          physics Physics {
                            density -1
                            mass 1.37
                            centerOfMass [
                              0 0.127 0
                            ]
                          }
                          linearVelocity 4.3015335044735584e-07 6.361455633245038e-05 1.2123910026464677e-07
                          angularVelocity 6.729475889107131e-07 -2.3089979894936188e-07 0.00018472919106329123
                        }
                      }
                    ]
                    name "forearm_link"
                    boundingObject Group {
                      children [
                        Pose {
                          translation 0 0 0.207
                          children [
                            Cylinder {
                              height 0.36
                              radius 0.038
                            }
                          ]
                        }
                        Pose {
                          translation 0 -0.001 0.39
                          rotation 1 0 0 -1.57079632679
                          children [
                            Cylinder {
                              height 0.109
                              radius 0.039
                            }
                          ]
                        }
                        Pose {
                          translation 0 0.06 0
                          rotation 1 0 0 1.57079632679
                          children [
                            Capsule {
                              height 0.05
                              radius 0.058
                              subdivision 16
                            }
                          ]
                        }
                        Pose {
                          translation 0 0 0.07
                          children [
                            Capsule {
                              height 0.1
                              radius 0.04
                              subdivision 16
                            }
                          ]
                        }
                      ]
                    }
                    physics Physics {
                      density -1
                      mass 2.846
                      centerOfMass [
                        0 0 0.15
                      ]
                    }
                    linearVelocity 4.595603361442666e-07 1.9233028284005912e-05 6.441400334670862e-08
                    angularVelocity 7.046962699850045e-07 -2.3659091786605524e-07 0.00018479465942318273
                  }
                }
              ]
              name "upper_arm_link"
              boundingObject Group {
                children [
                  Pose {
                    translation 0 0 0.22
                    children [
                      Cylinder {
                        height 0.407
                        radius 0.059
                      }
                    ]
                  }
                  Pose {
                    rotation 1 0 0 -1.57079632679
                    children [
                      Cylinder {
                        height 0.133
                        radius 0.059
                      }
                    ]
                  }
                  Pose {
                    translation 0 -0.005 0.424
                    rotation 1 0 0 -1.57079632679
                    children [
                      Cylinder {
                        height 0.149
                        radius 0.059
                      }
                    ]
                  }
                ]
              }
              physics Physics {
                density -1
                mass 8.058
                centerOfMass [
                  0 0 0.2125
                ]
              }
              linearVelocity 2.4814121263123444e-05 1.6315353076109638e-06 -3.7485479978722276e-08
              angularVelocity 6.014782947590954e-07 -2.2194322971888758e-07 0.0001849536087717978
            }
          }
        ]
        name "shoulder_link"
        boundingObject Group {
          children [
            Pose {
              children [
                Cylinder {
                  height 0.135
                  radius 0.059
                }
              ]
            }
            Pose {
              translation 0 0.03 0
              rotation 1 0 0 -1.57079632679
              children [
                Cylinder {
                  height 0.093
                  radius 0.059
                }
              ]
            }
          ]
        }
        physics Physics {
          density -1
          mass 3.761
          centerOfMass [
            0 -0.02561 0.00193
          ]
        }
        linearVelocity -5.072589993163856e-06 -4.6309012313259144e-07 8.185958759880736e-09
        angularVelocity 3.019962069305969e-07 -1.1031337291512798e-07 0.00018512033852205876
      }
    }
  ]
  name "UR5e"
  model "UR5e"
  boundingObject Pose {
    translation 0 0 0.05
    children [
      Cylinder {
        height 0.1
        radius 0.076
      }
    ]
  }
  controller "arm_controller"
  selfCollision TRUE
}
QRBox {
  translation 1.2601057796461599 0.8847473333573762 0.16997547500000004
  rotation -3.55455214030643e-18 -1.2199840505135025e-17 1 -2.9102849281991823
  name "A"
  color 1 0.6 0
  qrTexture [
    "../textures/qr.png"
  ]
}
DEF CONVEYOR_BELT Robot {
  translation 1.08 -0.725002 0.15
  children [
    Track {
      translation -2.7692400035306264e-06 0.14999999999989033 0.009855934855602128
      rotation -8.714120527145271e-07 1.0220982656396508e-06 0.9999999999990978 1.5708000321478908
      children [
        DEF BELT Shape {
          appearance PBRAppearance {
            baseColorMap ImageTexture {
              url [
                "https://raw.githubusercontent.com/cyberbotics/webots/R2025a/projects/samples/robotbenchmark/pick_and_place/worlds/textures/conveyor_belt_rubber.jpg"
              ]
            }
            roughness 1
            metalness 0
            textureTransform TextureTransform {
              rotation 1.5708
              scale 0.5 2
              translation -0.9016959999989008 0
            }
          }
          geometry Box {
            size 2.78 0.5 0.05
          }
        }
      ]
      boundingObject USE BELT
      physics Physics {
      }
      device [
        LinearMotor {
          name "belt motor"
        }
      ]
      textureAnimation 0.27 0
      linearVelocity 0 0 -6.013959132579346e-16
    }
    DEF CYL1 Pose {
      translation 0 1.28 0
      rotation 0 1 0 -1.570796
      children [
        DEF CYL Shape {
          appearance BrushedAluminium {
          }
          geometry Cylinder {
            height 0.5
            radius 0.03
          }
        }
      ]
    }
    DEF CYL2 Pose {
      translation 0 1.34 0
      rotation 0 1 0 -1.570796
      children [
        USE CYL
      ]
    }
    DEF CYL3 Pose {
      translation 0 1.4 0
      rotation 0 1 0 -1.570796
      children [
        USE CYL
      ]
    }
    DEF CYL4 Pose {
      translation 0 1.46 0
      rotation 0 1 0 -1.570796
      children [
        USE CYL
      ]
    }
    DEF CYL5 Pose {
      translation 0 1.52 0
      rotation 0 1 0 -1.570796
      children [
        USE CYL
      ]
    }
    DEF LEFT Pose {
      translation -0.26 0.31 0.01
      children [
        Shape {
          appearance BrushedAluminium {
          }
          geometry Box {
            size 0.02 3.1 0.1
          }
        }
      ]
    }
    DEF RIGHT Pose {
      translation 0.26 0.31 0.01
      children [
        Shape {
          appearance BrushedAluminium {
          }
          geometry Box {
            size 0.02 3.1 0.1
          }
        }
      ]
    }
    DEF BACK Pose {
      translation 0 1.87 0.01
      rotation 0 0 1 1.57079
      children [
        Shape {
          appearance BrushedAluminium {
          }
          geometry Box {
            size 0.02 0.54 0.1
          }
        }
      ]
    }
    DEF BOTTOM Pose {
      translation 0 1.69 -0.01
      rotation 0 0 1 1.5708
      children [
        Shape {
          appearance BrushedAluminium {
          }
          geometry Box {
            size 0.34 0.54 0.01
          }
        }
      ]
    }
    DEF FOOT1 Pose {
      translation 0.22 1.78 -0.1
      rotation 0 0 1 -1.5708
      children [
        Shape {
          appearance BrushedAluminium {
          }
          geometry Cylinder {
            height 0.12
            radius 0.03
          }
        }
      ]
    }
    DEF FOOT2 Pose {
      translation -0.22 1.78 -0.1
      rotation 0 0 1 -1.5708
      children [
        Shape {
          appearance BrushedAluminium {
          }
          geometry Cylinder {
            height 0.12
            radius 0.03
          }
        }
      ]
    }
    DEF FOOT3 Pose {
      translation -0.220005 0.159999 -0.1
      rotation 0 0 1 -1.5708
      children [
        Shape {
          appearance BrushedAluminium {
          }
          geometry Cylinder {
            height 0.12
            radius 0.03
          }
        }
      ]
    }
    DEF FOOT4 Pose {
      translation 0.220005 0.159999 -0.1
      rotation 0 0 1 -1.5708
      children [
        Shape {
          appearance BrushedAluminium {
          }
          geometry Cylinder {
            height 0.12
            radius 0.03
          }
        }
      ]
    }
  ]
  name "conveyor belt"
  boundingObject Group {
    children [
      USE CYL1
      USE CYL2
      USE CYL3
      USE CYL4
      USE CYL5
      USE LEFT
      USE RIGHT
      USE BOTTOM
      USE BACK
      USE FOOT1
      USE FOOT2
      USE FOOT3
      USE FOOT4
    ]
  }
  controller "belt_controller"
}
Robot {
  translation 0.4136656512576043 0.5151706117459821 0.01022041499968141
  rotation 3.411798324911927e-06 2.2973398349363598e-05 0.9999999997302914 1.5234072583380578
  children [
    HingeJoint {
      jointParameters HingeJointParameters {
        position 629.8495786590456
        axis 0 0 1
      }
      device [
        RotationalMotor {
          name "plate_motor"
          maxVelocity 6.28
          maxTorque 20
          sound ""
        }
        PositionSensor {
          name "plate_sensor"
        }
      ]
      endPoint Solid {
        translation 3.173431624750553e-08 5.5742054127482066e-08 0.11997247509779155
        rotation -3.343783453681413e-07 3.713800291139583e-07 -0.9999999999998752 4.752137366092592
        children [
          Shape {
            appearance OsbWood {
            }
            geometry Cylinder {
              height 0.02
              radius 0.15
            }
          }
        ]
        name "plate_disc"
        contactMaterial "sticky_plate"
        boundingObject Cylinder {
          height 0.02
          radius 0.15
        }
        physics Physics {
          density -1
          mass 0.5
        }
        linearVelocity -3.259173827715798e-06 4.724499548727347e-06 -2.215212602660599e-11
        angularVelocity -3.196688981881277e-07 4.771425467208636e-07 1.4946538426717848
      }
    }
  ]
  name "rotating_plate"
  boundingObject Cylinder {
    height 0.001
    radius 0.14
  }
  physics Physics {
    density -1
    mass 0.8
  }
  controller "plate_controller"
  synchronization FALSE
  linearVelocity -5.786906246565218e-09 2.4467796795186675e-08 -1.91824446578701e-11
  angularVelocity -3.979654666299816e-05 -2.666173114277768e-05 -2.412501164003597e-07
}
