#VRML_SIM R2025a utf8

EXTERNPROTO "https://raw.githubusercontent.com/cyberbotics/webots/R2025a/projects/objects/backgrounds/protos/TexturedBackground.proto"
EXTERNPROTO "https://raw.githubusercontent.com/cyberbotics/webots/R2025a/projects/objects/backgrounds/protos/TexturedBackgroundLight.proto"
EXTERNPROTO "https://raw.githubusercontent.com/cyberbotics/webots/R2025a/projects/objects/floors/protos/Floor.proto"
EXTERNPROTO "https://raw.githubusercontent.com/cyberbotics/webots/R2025a/projects/appearances/protos/CorrugatedMetal.proto"
EXTERNPROTO "https://raw.githubusercontent.com/cyberbotics/webots/R2025a/projects/objects/apartment_structure/protos/Ceiling.proto"
EXTERNPROTO "https://raw.githubusercontent.com/cyberbotics/webots/R2025a/projects/objects/apartment_structure/protos/Door.proto"
EXTERNPROTO "https://raw.githubusercontent.com/cyberbotics/webots/R2025a/projects/objects/apartment_structure/protos/DoorLever.proto"
EXTERNPROTO "https://raw.githubusercontent.com/cyberbotics/webots/R2025a/projects/objects/factory/valves/protos/LeverValve.proto"
EXTERNPROTO "https://raw.githubusercontent.com/cyberbotics/webots/R2025a/projects/objects/factory/pipes/protos/PipeSection.proto"
EXTERNPROTO "https://raw.githubusercontent.com/cyberbotics/webots/R2025a/projects/objects/factory/pipes/protos/LJoint.proto"
EXTERNPROTO "https://raw.githubusercontent.com/cyberbotics/webots/R2025a/projects/objects/factory/pipes/protos/TJoint.proto"
EXTERNPROTO "https://raw.githubusercontent.com/cyberbotics/webots/R2025a/projects/objects/factory/pallet/protos/WoodenPalletStack.proto"
EXTERNPROTO "../protos/WoodenBox.proto"
EXTERNPROTO "../protos/QRBox.proto"
EXTERNPROTO "https://raw.githubusercontent.com/cyberbotics/webots/R2025a/projects/appearances/protos/OsbWood.proto"
EXTERNPROTO "https://raw.githubusercontent.com/cyberbotics/webots/R2025a/projects/appearances/protos/BrushedAluminium.proto"
EXTERNPROTO "https://raw.githubusercontent.com/cyberbotics/webots/R2025a/projects/objects/floors/protos/RectangleArena.proto"
EXTERNPROTO "https://raw.githubusercontent.com/cyberbotics/webots/R2025a/projects/appearances/protos/Parquetry.proto"
EXTERNPROTO "https://raw.githubusercontent.com/cyberbotics/webots/R2025a/projects/objects/factory/containers/protos/MetalStorageBox.proto"

WorldInfo {
  title "Pick and Place"
  window "pick_and_place"
  basicTimeStep 16
  defaultDamping Damping {
  }
  contactProperties [
    ContactProperties {
      material2 "box"
      coulombFriction [
        10
      ]
    }
  ]
}
Viewpoint {
  orientation -0.3083649026155675 -0.06448566135406412 0.9490799156628595 3.5334551617775554
  position 2.405726930025783 0.7056074832781899 1.1834511580492884
  exposure 1.5
}
TexturedBackground {
  texture "factory"
}
TexturedBackgroundLight {
  texture "factory"
  castShadows FALSE
}
SpotLight {
  attenuation 0 0 1
  beamWidth 0.7
  intensity 10
  location 0 0 4
  castShadows TRUE
}
Floor {
  rotation 0 0 1 -1.5707963267948966
  size 12 12
  tileSize 1 1
  appearance PBRAppearance {
    baseColorMap ImageTexture {
      url [
        "../textures/concrete.jpg"
      ]
    }
    roughness 1
    metalness 0
  }
}
MetalStorageBox {
  translation 0.430001 1.74 0
  rotation 0 0 1 1.5708
}
RectangleArena {
  translation -0.43 0.83 0.01
  floorAppearance Parquetry {
    type "dark strip"
    colorOverride 0 0 1
  }
}
QRBox {
  translation 0.92822 -0.0572454 0.246037
  rotation 0.9115048374258994 -0.4112890821757928 0.0004714150811451633 3.1412590346034843
  name "C"
  color 1 0.6 0
  qrTexture [
    "../textures/qr2.png"
  ]
}
QRBox {
  translation 1.17011 0.534651 0.239975
  rotation -0.05938967739274558 0.705858649525238 0.705858649525238 -3.0229526542327343
  name "B"
  color 1 0.6 0
  qrTexture [
    "../textures/qr1.png"
  ]
}
DEF WALL Solid {
  translation 0 6 2.5
  rotation 1 0 0 1.5708
  children [
    DEF WALL_SHAPE Shape {
      appearance CorrugatedMetal {
        textureTransform TextureTransform {
          scale 2 2
        }
      }
      geometry Plane {
        size 12 5
      }
      castShadows FALSE
    }
  ]
  boundingObject USE WALL_SHAPE
}
DEF WALL Solid {
  translation 6 0 2.5
  rotation -0.5773509358508296 0.5773469358512743 0.5773529358506075 -2.094395307179586
  children [
    USE WALL_SHAPE
  ]
  name "solid(1)"
  boundingObject USE WALL_SHAPE
}
DEF WALL Solid {
  translation 0 -6 2.5
  rotation 3.808301514364728e-06 0.7071082811804253 0.7071052811792324 3.14159
  children [
    USE WALL_SHAPE
  ]
  name "solid(2)"
  boundingObject USE WALL_SHAPE
}
DEF WALL Solid {
  translation -6 0 2.5
  rotation -0.5773509358554485 -0.5773489358556708 -0.5773509358554485 -2.094395307179586
  children [
    USE WALL_SHAPE
  ]
  name "solid(3)"
  boundingObject USE WALL_SHAPE
}
Ceiling {
  translation 0 0 5
  size 12 12
  castShadows FALSE
}
Door {
  translation -2.45 5.96 0
  rotation 0 0 -1 1.5708
  size 0.01 1.2 2
  canBeOpen FALSE
  doorHandle DoorLever {
    translation 0 0 0.045
    mass 0
    hasStaticParent TRUE
    castShadows FALSE
  }
  castShadows FALSE
}
DEF PIPES Pose {
  rotation 0 0 1 -1.57
  children [
    LeverValve {
      translation 0.50999991 -5.83 1
      rotation 0 0 1 1.5708
      scale 1 1 1
    }
    PipeSection {
      translation 2.11 -5.86 0.96000003
      rotation 0.7071067811860158 0 0.7071067811860158 -3.1415853071795863
      height 3
      radius 0.07
    }
    PipeSection {
      translation -2.81 -5.86 0.9600001
      rotation 0.7071067811860158 0 0.7071067811860158 -3.1415853071795863
      name "pipe section(1)"
      height 6.4
      radius 0.07
    }
    PipeSection {
      translation -4.39 -5.87 3.83
      rotation 0.7071067811860158 0 0.7071067811860158 -3.1415853071795863
      name "pipe section(2)"
      height 3.3
      radius 0.07
    }
    PipeSection {
      translation -1.63 -5.86 0.65
      rotation 0.7071067811860158 0 0.7071067811860158 -3.1415853071795863
      name "pipe section(3)"
      height 8.8
      radius 0.07
    }
    PipeSection {
      translation 3.857 -5.86 0.34
      rotation 0 0 -1 -1.5707953071795862
      name "pipe section(4)"
      height 0.7
      radius 0.07
    }
    PipeSection {
      translation 3.037 -5.86 0.19
      rotation 0 0 -1 -1.5707953071795862
      name "pipe section(5)"
      height 0.4
      radius 0.07
    }
    PipeSection {
      translation -2.443 -5.84 2.37
      rotation 0 0 -1 -1.5707953071795862
      name "pipe section(6)"
      height 2.4
      radius 0.07
    }
    LJoint {
      translation 3.74 -5.8610001 0.85599996
      rotation 0 1 0 3.14159
      scale 2.4 2.4 2.4
    }
    LJoint {
      translation 2.93 -5.8610001 0.54599994
      rotation 0 1 0 3.14159
      name "L joint pipe(1)"
      scale 2.4 2.4 2.4
    }
    LJoint {
      translation -2.55 -5.845 3.7259999
      rotation 0 1 0 3.14159
      name "L joint pipe(2)"
      scale 2.4 2.4 2.4
    }
    TJoint {
      translation -2.44 -5.843 1.0259999
      rotation 0 1 0 3.14159
      scale 2.4 2.4 2.4
    }
  ]
}
WoodenPalletStack {
  translation 3.51824 5.0701 0.0986936
  rotation 0 0 1 -0.523595307179586
}
WoodenPalletStack {
  translation 5.0506856 4.3236115 0
  rotation 0 0 -1 1.0472
  name "wooden pallet stack(1)"
  palletNumber 2
}
WoodenBox {
  translation 5.0461957 -2.6920662 0.3
  rotation 0 0 1 -1.5707963267948966
}
WoodenBox {
  translation 5.0297142 -3.3127088 0.3
  rotation 0 0 1 -1.5707963267948966
  name "wooden box(1)"
}
WoodenBox {
  translation 5.0890438 -2.0668732 0.3
  rotation 0 0 -1 1.571421196638078
  name "wooden box(2)"
}
WoodenBox {
  translation 5.0324568 -3.0679729 0.9
  rotation 0.004999875004687304 0.004999875004687304 -0.9999750009374608 1.570821326586566
  name "wooden box(3)"
}
QRBox {
  translation 1.05133 0.332125 0.269975
  rotation 1.7892568478649135e-17 -1.2835581998517654e-17 1 -2.9102849281991823
  name "A"
  color 1 0.6 0
  qrTexture [
    "../textures/qr.png"
  ]
}
DEF CONVEYOR_BELT Robot {
  translation 1.08 -0.725002 0.15
  children [
    Track {
      translation -2.76924e-06 0.15 0.00604095
      rotation -8.714120527145271e-07 1.0220982656396508e-06 0.9999999999990978 1.5708000321478908
      children [
        DEF BELT Shape {
          appearance PBRAppearance {
            baseColorMap ImageTexture {
              url [
                "https://raw.githubusercontent.com/cyberbotics/webots/R2025a/projects/samples/robotbenchmark/pick_and_place/worlds/textures/conveyor_belt_rubber.jpg"
              ]
            }
            roughness 1
            metalness 0
            textureTransform TextureTransform {
              rotation 1.5708
              scale 0.5 2
              translation -0.09225599999875499 0
            }
          }
          geometry Box {
            size 2.78 0.5 0.05
          }
        }
      ]
      boundingObject USE BELT
      physics Physics {
      }
      device [
        LinearMotor {
          name "belt motor"
        }
      ]
      textureAnimation 0.27 0
    }
    DEF CYL1 Pose {
      translation 0 1.28 0
      rotation 0 1 0 -1.570796
      children [
        DEF CYL Shape {
          appearance BrushedAluminium {
          }
          geometry Cylinder {
            height 0.5
            radius 0.03
          }
        }
      ]
    }
    DEF CYL2 Pose {
      translation 0 1.34 0
      rotation 0 1 0 -1.570796
      children [
        USE CYL
      ]
    }
    DEF CYL3 Pose {
      translation 0 1.4 0
      rotation 0 1 0 -1.570796
      children [
        USE CYL
      ]
    }
    DEF CYL4 Pose {
      translation 0 1.46 0
      rotation 0 1 0 -1.570796
      children [
        USE CYL
      ]
    }
    DEF CYL5 Pose {
      translation 0 1.52 0
      rotation 0 1 0 -1.570796
      children [
        USE CYL
      ]
    }
    DEF LEFT Pose {
      translation -0.26 0.31 0.01
      children [
        Shape {
          appearance BrushedAluminium {
          }
          geometry Box {
            size 0.02 3.1 0.1
          }
        }
      ]
    }
    DEF RIGHT Pose {
      translation 0.26 0.31 0.01
      children [
        Shape {
          appearance BrushedAluminium {
          }
          geometry Box {
            size 0.02 3.1 0.1
          }
        }
      ]
    }
    DEF BACK Pose {
      translation 0 1.87 0.01
      rotation 0 0 1 1.57079
      children [
        Shape {
          appearance BrushedAluminium {
          }
          geometry Box {
            size 0.02 0.54 0.1
          }
        }
      ]
    }
    DEF BOTTOM Pose {
      translation 0 1.69 -0.01
      rotation 0 0 1 1.5708
      children [
        Shape {
          appearance BrushedAluminium {
          }
          geometry Box {
            size 0.34 0.54 0.01
          }
        }
      ]
    }
    DEF FOOT1 Pose {
      translation 0.22 1.78 -0.1
      rotation 0 0 1 -1.5708
      children [
        Shape {
          appearance BrushedAluminium {
          }
          geometry Cylinder {
            height 0.12
            radius 0.03
          }
        }
      ]
    }
    DEF FOOT2 Pose {
      translation -0.22 1.78 -0.1
      rotation 0 0 1 -1.5708
      children [
        Shape {
          appearance BrushedAluminium {
          }
          geometry Cylinder {
            height 0.12
            radius 0.03
          }
        }
      ]
    }
    DEF FOOT3 Pose {
      translation -0.220005 0.159999 -0.1
      rotation 0 0 1 -1.5708
      children [
        Shape {
          appearance BrushedAluminium {
          }
          geometry Cylinder {
            height 0.12
            radius 0.03
          }
        }
      ]
    }
    DEF FOOT4 Pose {
      translation 0.220005 0.159999 -0.1
      rotation 0 0 1 -1.5708
      children [
        Shape {
          appearance BrushedAluminium {
          }
          geometry Cylinder {
            height 0.12
            radius 0.03
          }
        }
      ]
    }
    Receiver {
      channel 1
    }
  ]
  name "conveyor belt"
  boundingObject Group {
    children [
      USE CYL1
      USE CYL2
      USE CYL3
      USE CYL4
      USE CYL5
      USE LEFT
      USE RIGHT
      USE BOTTOM
      USE BACK
      USE FOOT1
      USE FOOT2
      USE FOOT3
      USE FOOT4
    ]
  }
  controller "belt_controller"
}
Robot {
  translation 0.4136651424142337 0.5151708318376059 0.010220414035433834
  rotation -0.00025604093138270053 5.5929812777309715e-05 0.9999999656574483 1.5233431067902308
  children [
    HingeJoint {
      jointParameters HingeJointParameters {
        position 973.7530668950691
        axis 0 0 1
      }
      device [
        RotationalMotor {
          name "plate_motor"
          maxVelocity 6.28
          maxTorque 20
          sound ""
        }
        PositionSensor {
          name "plate_sensor"
        }
      ]
      endPoint Solid {
        translation 5.2261710355857105e-08 -3.718813058931977e-08 0.11997247509779119
        rotation -5.049086515716848e-07 -4.8926208876451185e-06 -0.9999999999879036 0.14065571776865524
        children [
          Shape {
            appearance OsbWood {
            }
            geometry Cylinder {
              height 0.02
              radius 0.15
            }
          }
        ]
        name "plate_disc"
        contactMaterial "sticky_plate"
        boundingObject Cylinder {
          height 0.02
          radius 0.15
        }
        physics Physics {
          density -1
          mass 0.5
        }
      }
    }
    Receiver {
      channel 1
    }
    Emitter {
      channel 2
    }
  ]
  name "rotating_plate"
  boundingObject Cylinder {
    height 0.001
    radius 0.14
  }
  physics Physics {
    density -1
    mass 0.8
  }
  controller "plate_controller"
  synchronization FALSE
}
Robot {
  translation 0.39 1.02 0
  rotation 0 0 1 -1.5707953071795862
  children [
    Emitter {
      channel 1
    }
    Receiver {
      channel 2
    }
    Camera {
      translation 0.77805 0.0328296 0.18
      rotation 1.32679e-06 1.59084e-06 1 3.14159
      name "side_camera"
      fieldOfView 1
      width 1280
      height 720
      far 100
      recognition Recognition {
      }
    }
    Camera {
      translation 0.0942022 0.688368 0.690308
      rotation 0.6597579156185216 0.018277297662376818 -0.7512559039161452 -3.1291253071795864
      name "top_camera"
      fieldOfView 1
      width 1280
      height 720
      far 100
      recognition Recognition {
      }
    }
    Pose {
      translation -0.0467 0.047 0.0252
      rotation 1 0 0 -3.1415923071795864
      children [
        DEF SCREW Group {
          children [
            Transform {
              scale 1.1 1.1 1.1
              children [
                Shape {
                  appearance PBRAppearance {
                    baseColorMap ImageTexture {
                      url [
                        "https://raw.githubusercontent.com/cyberbotics/webots/R2025a/projects/appearances/protos/textures/old_steel/old_steel_base_color.jpg"
                      ]
                    }
                    roughnessMap ImageTexture {
                      url [
                        "https://raw.githubusercontent.com/cyberbotics/webots/R2025a/projects/appearances/protos/textures/old_steel/old_steel_roughness.jpg"
                      ]
                    }
                    metalnessMap ImageTexture {
                      url [
                        "https://raw.githubusercontent.com/cyberbotics/webots/R2025a/projects/appearances/protos/textures/old_steel/old_steel_metalness.jpg"
                      ]
                    }
                    normalMap ImageTexture {
                      url [
                        "https://raw.githubusercontent.com/cyberbotics/webots/R2025a/projects/appearances/protos/textures/old_steel/old_steel_normal.jpg"
                      ]
                    }
                  }
                  geometry Mesh {
                    url [
                      "https://raw.githubusercontent.com/cyberbotics/webots/R2025a/projects/robots/universal_robots/protos/UR5e/meshes/screw.obj"
                    ]
                  }
                }
              ]
            }
            DEF CYLINDER Pose {
              translation 0 0 0.02
              children [
                Shape {
                  appearance PBRAppearance {
                    baseColorMap ImageTexture {
                      url [
                        "https://raw.githubusercontent.com/cyberbotics/webots/R2025a/projects/appearances/protos/textures/screw_thread/screw_thread_base_color.jpg"
                      ]
                    }
                    roughnessMap ImageTexture {
                      url [
                        "https://raw.githubusercontent.com/cyberbotics/webots/R2025a/projects/appearances/protos/textures/screw_thread/screw_thread_roughness.jpg"
                      ]
                    }
                    normalMap ImageTexture {
                      url [
                        "https://raw.githubusercontent.com/cyberbotics/webots/R2025a/projects/appearances/protos/textures/screw_thread/screw_thread_normal.jpg"
                      ]
                    }
                    occlusionMap ImageTexture {
                      url [
                        "https://raw.githubusercontent.com/cyberbotics/webots/R2025a/projects/appearances/protos/textures/screw_thread/screw_thread_occlusion.jpg"
                      ]
                    }
                    textureTransform TextureTransform {
                      rotation 1.5708
                      scale 1.6 2
                    }
                  }
                  geometry Cylinder {
                    height 0.04
                    radius 0.0044
                  }
                }
              ]
            }
          ]
        }
      ]
    }
    Pose {
      translation -0.0467 -0.047 0.0252
      rotation 1 0 0 -3.1415923071795864
      children [
        USE SCREW
      ]
    }
    Pose {
      translation 0.0464 -0.047 0.0252
      rotation 1 0 0 -3.1415923071795864
      children [
        USE SCREW
      ]
    }
    Pose {
      translation 0.0464 0.047 0.0252
      rotation 1 0 0 -3.1415923071795864
      children [
        USE SCREW
      ]
    }
    Shape {
      appearance DEF METAL_APPEARANCE PBRAppearance {
        baseColor 0.6 0.6 0.6
        roughness 0.7
      }
      geometry Mesh {
        url [
          "https://raw.githubusercontent.com/cyberbotics/webots/R2025a/projects/robots/universal_robots/protos/UR5e/meshes/base_link_0.obj"
        ]
      }
    }
    Shape {
      appearance DEF JOINT_APPEARANCE PBRAppearance {
        baseColor 0 0 0
        roughness 1
        metalness 0
      }
      geometry Mesh {
        url [
          "https://raw.githubusercontent.com/cyberbotics/webots/R2025a/projects/robots/universal_robots/protos/UR5e/meshes/base_link_1.obj"
        ]
      }
    }
    HingeJoint {
      jointParameters HingeJointParameters {
        position -1.4684411589511993e-05
        axis 0 0 1
        anchor 0 0 0.163
      }
      device [
        RotationalMotor {
          name "shoulder_pan_joint"
          maxVelocity 3.14
          minPosition -6.28318530718
          maxPosition 6.28318530718
          maxTorque 150
        }
        PositionSensor {
          name "shoulder_pan_joint_sensor"
        }
      ]
      endPoint Solid {
        translation 0 0 0.163
        rotation 0 0 -1 1.4684412032347945e-05
        children [
          Shape {
            appearance USE METAL_APPEARANCE
            geometry Mesh {
              url [
                "https://raw.githubusercontent.com/cyberbotics/webots/R2025a/projects/robots/universal_robots/protos/UR5e/meshes/shoulder_link_0.obj"
              ]
            }
          }
          Shape {
            appearance USE JOINT_APPEARANCE
            geometry Mesh {
              url [
                "https://raw.githubusercontent.com/cyberbotics/webots/R2025a/projects/robots/universal_robots/protos/UR5e/meshes/shoulder_link_1.obj"
              ]
            }
          }
          Shape {
            appearance PBRAppearance {
              baseColor 0.4902 0.678431 0.8
              roughness 0.4
              metalness 0
              normalMap ImageTexture {
                url [
                  "https://raw.githubusercontent.com/cyberbotics/webots/R2025a/projects/robots/universal_robots/protos/UR5e/textures/normal_0.jpg"
                ]
              }
              occlusionMap ImageTexture {
                url [
                  "https://raw.githubusercontent.com/cyberbotics/webots/R2025a/projects/robots/universal_robots/protos/UR5e/textures/occlusion_0.jpg"
                ]
              }
            }
            geometry Mesh {
              url [
                "https://raw.githubusercontent.com/cyberbotics/webots/R2025a/projects/robots/universal_robots/protos/UR5e/meshes/shoulder_link_2.obj"
              ]
            }
          }
          Shape {
            appearance DEF SCREW_APPEARANCE PBRAppearance {
            }
            geometry Mesh {
              url [
                "https://raw.githubusercontent.com/cyberbotics/webots/R2025a/projects/robots/universal_robots/protos/UR5e/meshes/shoulder_link_3.obj"
              ]
            }
          }
          HingeJoint {
            jointParameters HingeJointParameters {
              position -1.5707963199094739
              axis 0 1 0
              anchor 0 0.138 0
            }
            device [
              RotationalMotor {
                name "shoulder_lift_joint"
                maxVelocity 3.14
                minPosition -6.28318530718
                maxPosition 6.28318530718
                maxTorque 150
              }
              PositionSensor {
                name "shoulder_lift_joint_sensor"
              }
            ]
            endPoint Solid {
              translation 0 0.138 0
              rotation 0 -1 0 3.182017282256878e-07
              children [
                Shape {
                  appearance PBRAppearance {
                    baseColor 0.4902 0.678431 0.8
                    roughness 0.4
                    metalness 0
                    normalMap ImageTexture {
                      url [
                        "https://raw.githubusercontent.com/cyberbotics/webots/R2025a/projects/robots/universal_robots/protos/UR5e/textures/normal_1.jpg"
                      ]
                    }
                    occlusionMap ImageTexture {
                      url [
                        "https://raw.githubusercontent.com/cyberbotics/webots/R2025a/projects/robots/universal_robots/protos/UR5e/textures/occlusion_1.jpg"
                      ]
                    }
                  }
                  geometry Mesh {
                    url [
                      "https://raw.githubusercontent.com/cyberbotics/webots/R2025a/projects/robots/universal_robots/protos/UR5e/meshes/upper_arm_link_0.obj"
                    ]
                  }
                }
                Shape {
                  appearance USE SCREW_APPEARANCE
                  geometry Mesh {
                    url [
                      "https://raw.githubusercontent.com/cyberbotics/webots/R2025a/projects/robots/universal_robots/protos/UR5e/meshes/upper_arm_link_1.obj"
                    ]
                  }
                }
                Shape {
                  appearance USE METAL_APPEARANCE
                  geometry Mesh {
                    url [
                      "https://raw.githubusercontent.com/cyberbotics/webots/R2025a/projects/robots/universal_robots/protos/UR5e/meshes/upper_arm_link_2.obj"
                    ]
                  }
                }
                Shape {
                  appearance USE JOINT_APPEARANCE
                  geometry Mesh {
                    url [
                      "https://raw.githubusercontent.com/cyberbotics/webots/R2025a/projects/robots/universal_robots/protos/UR5e/meshes/upper_arm_link_3.obj"
                    ]
                  }
                }
                Shape {
                  appearance PBRAppearance {
                    baseColor 0.4902 0.678431 0.8
                    roughness 0.4
                    metalness 0
                    normalMap ImageTexture {
                      url [
                        "https://raw.githubusercontent.com/cyberbotics/webots/R2025a/projects/robots/universal_robots/protos/UR5e/textures/normal_2.jpg"
                      ]
                    }
                    occlusionMap ImageTexture {
                      url [
                        "https://raw.githubusercontent.com/cyberbotics/webots/R2025a/projects/robots/universal_robots/protos/UR5e/textures/occlusion_2.jpg"
                      ]
                    }
                  }
                  geometry Mesh {
                    url [
                      "https://raw.githubusercontent.com/cyberbotics/webots/R2025a/projects/robots/universal_robots/protos/UR5e/meshes/upper_arm_link_4.obj"
                    ]
                  }
                }
                Shape {
                  appearance USE SCREW_APPEARANCE
                  geometry Mesh {
                    url [
                      "https://raw.githubusercontent.com/cyberbotics/webots/R2025a/projects/robots/universal_robots/protos/UR5e/meshes/upper_arm_link_5.obj"
                    ]
                  }
                }
                Shape {
                  appearance DEF METAL_APPEARANCE_LIGHT PBRAppearance {
                    roughness 0.7
                  }
                  geometry Mesh {
                    url [
                      "https://raw.githubusercontent.com/cyberbotics/webots/R2025a/projects/robots/universal_robots/protos/UR5e/meshes/upper_arm_link_6.obj"
                    ]
                  }
                }
                Shape {
                  appearance USE JOINT_APPEARANCE
                  geometry Mesh {
                    url [
                      "https://raw.githubusercontent.com/cyberbotics/webots/R2025a/projects/robots/universal_robots/protos/UR5e/meshes/upper_arm_link_7.obj"
                    ]
                  }
                }
                Shape {
                  appearance USE METAL_APPEARANCE
                  geometry Mesh {
                    url [
                      "https://raw.githubusercontent.com/cyberbotics/webots/R2025a/projects/robots/universal_robots/protos/UR5e/meshes/upper_arm_link_8.obj"
                    ]
                  }
                }
                Shape {
                  appearance USE JOINT_APPEARANCE
                  geometry Mesh {
                    url [
                      "https://raw.githubusercontent.com/cyberbotics/webots/R2025a/projects/robots/universal_robots/protos/UR5e/meshes/upper_arm_link_9.obj"
                    ]
                  }
                }
                HingeJoint {
                  jointParameters HingeJointParameters {
                    position -8.718194807435164e-10
                    axis 0 1 0
                    anchor 0 -0.131 0.425
                  }
                  device [
                    RotationalMotor {
                      name "elbow_joint"
                      maxVelocity 3.14
                      minPosition -3.14159265359
                      maxPosition 3.14159265359
                      maxTorque 150
                    }
                    PositionSensor {
                      name "elbow_joint_sensor"
                    }
                  ]
                  endPoint Solid {
                    translation 0 -0.131 0.425
                    rotation 0 1 0 0
                    children [
                      Shape {
                        appearance USE METAL_APPEARANCE
                        geometry Mesh {
                          url [
                            "https://raw.githubusercontent.com/cyberbotics/webots/R2025a/projects/robots/universal_robots/protos/UR5e/meshes/forearm_link_0.obj"
                          ]
                        }
                      }
                      Shape {
                        appearance USE METAL_APPEARANCE
                        geometry Mesh {
                          url [
                            "https://raw.githubusercontent.com/cyberbotics/webots/R2025a/projects/robots/universal_robots/protos/UR5e/meshes/forearm_link_1.obj"
                          ]
                        }
                      }
                      Shape {
                        appearance USE JOINT_APPEARANCE
                        geometry Mesh {
                          url [
                            "https://raw.githubusercontent.com/cyberbotics/webots/R2025a/projects/robots/universal_robots/protos/UR5e/meshes/forearm_link_2.obj"
                          ]
                        }
                      }
                      Shape {
                        appearance USE METAL_APPEARANCE_LIGHT
                        geometry Mesh {
                          url [
                            "https://raw.githubusercontent.com/cyberbotics/webots/R2025a/projects/robots/universal_robots/protos/UR5e/meshes/forearm_link_3.obj"
                          ]
                        }
                      }
                      Shape {
                        appearance USE JOINT_APPEARANCE
                        geometry Mesh {
                          url [
                            "https://raw.githubusercontent.com/cyberbotics/webots/R2025a/projects/robots/universal_robots/protos/UR5e/meshes/forearm_link_4.obj"
                          ]
                        }
                      }
                      Shape {
                        appearance PBRAppearance {
                          baseColor 0.4902 0.678431 0.8
                          roughness 0.4
                          metalness 0
                          normalMap ImageTexture {
                            url [
                              "https://raw.githubusercontent.com/cyberbotics/webots/R2025a/projects/robots/universal_robots/protos/UR5e/textures/normal_3.jpg"
                            ]
                          }
                          occlusionMap ImageTexture {
                            url [
                              "https://raw.githubusercontent.com/cyberbotics/webots/R2025a/projects/robots/universal_robots/protos/UR5e/textures/occlusion_3.jpg"
                            ]
                          }
                        }
                        geometry Mesh {
                          url [
                            "https://raw.githubusercontent.com/cyberbotics/webots/R2025a/projects/robots/universal_robots/protos/UR5e/meshes/forearm_link_5.obj"
                          ]
                        }
                      }
                      Shape {
                        appearance USE SCREW_APPEARANCE
                        geometry Mesh {
                          url [
                            "https://raw.githubusercontent.com/cyberbotics/webots/R2025a/projects/robots/universal_robots/protos/UR5e/meshes/forearm_link_6.obj"
                          ]
                        }
                      }
                      Shape {
                        appearance USE JOINT_APPEARANCE
                        geometry Mesh {
                          url [
                            "https://raw.githubusercontent.com/cyberbotics/webots/R2025a/projects/robots/universal_robots/protos/UR5e/meshes/forearm_link_7.obj"
                          ]
                        }
                      }
                      HingeJoint {
                        jointParameters HingeJointParameters {
                          position -1.5707963191322973
                          axis 0 1 0
                          anchor 0 0 0.392
                        }
                        device [
                          RotationalMotor {
                            name "wrist_1_joint"
                            maxVelocity 6.28
                            minPosition -6.28318530718
                            maxPosition 6.28318530718
                            maxTorque 28
                          }
                          PositionSensor {
                            name "wrist_1_joint_sensor"
                          }
                        ]
                        endPoint Solid {
                          translation 0 0 0.392
                          rotation 0 -1 0 3.182017282256878e-07
                          children [
                            Shape {
                              appearance USE METAL_APPEARANCE
                              geometry Mesh {
                                url [
                                  "https://raw.githubusercontent.com/cyberbotics/webots/R2025a/projects/robots/universal_robots/protos/UR5e/meshes/wrist_1_link_0.obj"
                                ]
                              }
                            }
                            Shape {
                              appearance PBRAppearance {
                                baseColor 0.4902 0.678431 0.8
                                roughness 0.4
                                metalness 0
                                normalMap ImageTexture {
                                  url [
                                    "https://raw.githubusercontent.com/cyberbotics/webots/R2025a/projects/robots/universal_robots/protos/UR5e/textures/normal_4.jpg"
                                  ]
                                }
                                occlusionMap ImageTexture {
                                  url [
                                    "https://raw.githubusercontent.com/cyberbotics/webots/R2025a/projects/robots/universal_robots/protos/UR5e/textures/occlusion_4.jpg"
                                  ]
                                }
                              }
                              geometry Mesh {
                                url [
                                  "https://raw.githubusercontent.com/cyberbotics/webots/R2025a/projects/robots/universal_robots/protos/UR5e/meshes/wrist_1_link_1.obj"
                                ]
                              }
                            }
                            Shape {
                              appearance USE SCREW_APPEARANCE
                              geometry Mesh {
                                url [
                                  "https://raw.githubusercontent.com/cyberbotics/webots/R2025a/projects/robots/universal_robots/protos/UR5e/meshes/wrist_1_link_2.obj"
                                ]
                              }
                            }
                            Shape {
                              appearance USE JOINT_APPEARANCE
                              geometry Mesh {
                                url [
                                  "https://raw.githubusercontent.com/cyberbotics/webots/R2025a/projects/robots/universal_robots/protos/UR5e/meshes/wrist_1_link_3.obj"
                                ]
                              }
                            }
                            HingeJoint {
                              jointParameters HingeJointParameters {
                                position 1.6016411602236848e-10
                                axis 0 0 1
                                anchor 0 0.127 0
                              }
                              device [
                                RotationalMotor {
                                  name "wrist_2_joint"
                                  maxVelocity 6.28
                                  minPosition -6.28318530718
                                  maxPosition 6.28318530718
                                  maxTorque 28
                                }
                                PositionSensor {
                                  name "wrist_2_joint_sensor"
                                }
                              ]
                              endPoint Solid {
                                translation 0 0.127 0
                                children [
                                  Shape {
                                    appearance USE METAL_APPEARANCE
                                    geometry Mesh {
                                      url [
                                        "https://raw.githubusercontent.com/cyberbotics/webots/R2025a/projects/robots/universal_robots/protos/UR5e/meshes/wrist_2_link_0.obj"
                                      ]
                                    }
                                  }
                                  Shape {
                                    appearance PBRAppearance {
                                      baseColor 0.4902 0.678431 0.8
                                      roughness 0.4
                                      metalness 0
                                      normalMap ImageTexture {
                                        url [
                                          "https://raw.githubusercontent.com/cyberbotics/webots/R2025a/projects/robots/universal_robots/protos/UR5e/textures/normal_5.jpg"
                                        ]
                                      }
                                      occlusionMap ImageTexture {
                                        url [
                                          "https://raw.githubusercontent.com/cyberbotics/webots/R2025a/projects/robots/universal_robots/protos/UR5e/textures/occlusion_5.jpg"
                                        ]
                                      }
                                    }
                                    geometry Mesh {
                                      url [
                                        "https://raw.githubusercontent.com/cyberbotics/webots/R2025a/projects/robots/universal_robots/protos/UR5e/meshes/wrist_2_link_1.obj"
                                      ]
                                    }
                                  }
                                  Shape {
                                    appearance USE SCREW_APPEARANCE
                                    geometry Mesh {
                                      url [
                                        "https://raw.githubusercontent.com/cyberbotics/webots/R2025a/projects/robots/universal_robots/protos/UR5e/meshes/wrist_2_link_2.obj"
                                      ]
                                    }
                                  }
                                  Shape {
                                    appearance USE JOINT_APPEARANCE
                                    geometry Mesh {
                                      url [
                                        "https://raw.githubusercontent.com/cyberbotics/webots/R2025a/projects/robots/universal_robots/protos/UR5e/meshes/wrist_2_link_3.obj"
                                      ]
                                    }
                                  }
                                  HingeJoint {
                                    jointParameters HingeJointParameters {
                                      position -4.3177929065787936e-12
                                      axis 0 1 0
                                      anchor 0 0 0.1
                                    }
                                    device [
                                      RotationalMotor {
                                        name "wrist_3_joint"
                                        maxVelocity 6.28
                                        minPosition -6.28318530718
                                        maxPosition 6.28318530718
                                        maxTorque 28
                                      }
                                      PositionSensor {
                                        name "wrist_3_joint_sensor"
                                      }
                                    ]
                                    endPoint Solid {
                                      translation 0 0 0.1
                                      rotation 0 1 0 0
                                      children [
                                        Shape {
                                          appearance USE METAL_APPEARANCE
                                          geometry Mesh {
                                            url [
                                              "https://raw.githubusercontent.com/cyberbotics/webots/R2025a/projects/robots/universal_robots/protos/UR5e/meshes/wrist_3_link_0.obj"
                                            ]
                                          }
                                        }
                                        Pose {
                                          translation 0 0.1 0
                                          children [
                                            DEF GRIPPER_BASE Solid {
                                              rotation 0 0 1 1.5708
                                              children [
                                                DEF LIFT_SLIDER SliderJoint {
                                                  jointParameters JointParameters {
                                                    position -1.571458477346593e-05
                                                    axis 0 0 -1
                                                  }
                                                  device [
                                                    LinearMotor {
                                                      name "lift motor"
                                                      minPosition -0.05
                                                      maxPosition 0.05
                                                    }
                                                  ]
                                                  endPoint DEF LIFT Solid {
                                                    translation 0.042500004946005365 -7.747869013030595e-10 1.5721186712922203e-05
                                                    rotation 0.5773502691896258 -0.5773502691896258 -0.5773502691896258 2.0944
                                                    children [
                                                      DEF LEFT_FINGER_SLIDER SliderJoint {
                                                        jointParameters JointParameters {
                                                          position -1.4140555845811497e-10
                                                          axis -1 0 0
                                                        }
                                                        device [
                                                          LinearMotor {
                                                            name "finger motor::left"
                                                            minPosition -1.8020568378662854e-10
                                                            maxPosition 0.1
                                                          }
                                                        ]
                                                        endPoint DEF LEFT_FINGER Solid {
                                                          translation -0.02199999985859444 0 -0.02
                                                          children [
                                                            Group {
                                                              children [
                                                                Pose {
                                                                  translation 0 0.0015 -0.003
                                                                  children [
                                                                    Shape {
                                                                      appearance DEF METAL_APPEARANCE PBRAppearance {
                                                                        baseColorMap ImageTexture {
                                                                          url [
                                                                            "https://raw.githubusercontent.com/cyberbotics/webots/R2025a/projects/default/worlds/textures/metal.jpg"
                                                                          ]
                                                                        }
                                                                        roughness 0.2
                                                                      }
                                                                      geometry Box {
                                                                        size 0.018 0.031 0.036
                                                                      }
                                                                    }
                                                                  ]
                                                                }
                                                                DEF LEFT_FINGER_TRANSFORM Pose {
                                                                  translation 0.0015 -0.006 -0.069
                                                                  children [
                                                                    Shape {
                                                                      appearance DEF BLACK_APPEARANCE PBRAppearance {
                                                                        baseColor 0.0705882 0.0705882 0.0705882
                                                                        roughness 0.4
                                                                        metalness 0
                                                                      }
                                                                      geometry Box {
                                                                        size 0.015 0.035 0.095
                                                                      }
                                                                    }
                                                                  ]
                                                                }
                                                              ]
                                                            }
                                                          ]
                                                          name "left finger"
                                                          boundingObject USE LEFT_FINGER_TRANSFORM
                                                          physics DEF LEFT_FINGER_PHYSICS Physics {
                                                          }
                                                        }
                                                      }
                                                      DEF RIGHT_FINGER_SLIDER SliderJoint {
                                                        jointParameters JointParameters {
                                                          position 1.930135053423106e-10
                                                          axis 1 0 0
                                                        }
                                                        device [
                                                          LinearMotor {
                                                            name "finger motor::right"
                                                            minPosition -1.8020568378662854e-10
                                                            maxPosition 0.1
                                                          }
                                                        ]
                                                        endPoint DEF RIGHT_FINGER Solid {
                                                          translation 0.022000000193013503 0 -0.02
                                                          children [
                                                            Group {
                                                              children [
                                                                Pose {
                                                                  translation 0 0.0015 -0.003
                                                                  children [
                                                                    Shape {
                                                                      appearance USE METAL_APPEARANCE
                                                                      geometry Box {
                                                                        size 0.018 0.031 0.036
                                                                      }
                                                                    }
                                                                  ]
                                                                }
                                                                DEF RIGHT_FINGER_TRANSFORM Pose {
                                                                  translation -0.0015 -0.006 -0.069
                                                                  children [
                                                                    Shape {
                                                                      appearance USE BLACK_APPEARANCE
                                                                      geometry Box {
                                                                        size 0.015 0.035 0.095
                                                                      }
                                                                    }
                                                                  ]
                                                                }
                                                              ]
                                                            }
                                                          ]
                                                          name "right finger"
                                                          boundingObject USE RIGHT_FINGER_TRANSFORM
                                                          physics USE LEFT_FINGER_PHYSICS
                                                        }
                                                      }
                                                      Pose {
                                                        translation 0 -0.126 0.135
                                                        children [
                                                          Group {
                                                            children [
                                                              Pose {
                                                                translation 0 0.1478 -0.154
                                                                children [
                                                                  DEF UPPER_BOX Shape {
                                                                    appearance USE BLACK_APPEARANCE
                                                                    geometry Box {
                                                                      size 0.315 0.01 0.043419
                                                                    }
                                                                  }
                                                                ]
                                                              }
                                                              Pose {
                                                                translation 0 0.1072 -0.154
                                                                children [
                                                                  USE UPPER_BOX
                                                                ]
                                                              }
                                                              Pose {
                                                                translation -0.155 0.1275 -0.154
                                                                children [
                                                                  DEF LEFT_BOX Shape {
                                                                    appearance USE BLACK_APPEARANCE
                                                                    geometry Box {
                                                                      size 0.007 0.05 0.042227
                                                                    }
                                                                  }
                                                                ]
                                                              }
                                                              Pose {
                                                                translation 0.155 0.1275 -0.154
                                                                children [
                                                                  USE LEFT_BOX
                                                                ]
                                                              }
                                                              Pose {
                                                                translation 0 0.126 -0.158
                                                                children [
                                                                  DEF CENTER_BOX Shape {
                                                                    appearance USE BLACK_APPEARANCE
                                                                    geometry Box {
                                                                      size 0.027 0.0341 0.035
                                                                    }
                                                                  }
                                                                ]
                                                              }
                                                              Pose {
                                                                translation 0 0.132 -0.154
                                                                rotation -0.5773489358556708 -0.5773509358554485 0.5773509358554485 2.094397
                                                                children [
                                                                  DEF UPPER_CYLINDER Shape {
                                                                    appearance USE METAL_APPEARANCE
                                                                    geometry Cylinder {
                                                                      height 0.3
                                                                      radius 0.00225
                                                                    }
                                                                  }
                                                                ]
                                                              }
                                                              Pose {
                                                                translation 0 0.118 -0.154
                                                                rotation -0.5773489358556708 -0.5773509358554485 0.5773509358554485 2.094397
                                                                children [
                                                                  Shape {
                                                                    appearance USE METAL_APPEARANCE
                                                                    geometry Cylinder {
                                                                      height 0.3
                                                                      radius 0.00125
                                                                    }
                                                                  }
                                                                ]
                                                              }
                                                              Pose {
                                                                translation -0.041 0.155 -0.148
                                                                children [
                                                                  Shape {
                                                                    appearance USE BLACK_APPEARANCE
                                                                    geometry Box {
                                                                      size 0.0141907 0.006 0.04
                                                                    }
                                                                  }
                                                                ]
                                                              }
                                                              Pose {
                                                                translation -0.036 0.145 -0.116
                                                                children [
                                                                  Shape {
                                                                    appearance USE METAL_APPEARANCE
                                                                    geometry Box {
                                                                      size 0.027 0.03 0.03
                                                                    }
                                                                  }
                                                                ]
                                                              }
                                                              Pose {
                                                                translation 0.041 0.155 -0.148
                                                                children [
                                                                  Shape {
                                                                    appearance USE BLACK_APPEARANCE
                                                                    geometry Box {
                                                                      size 0.0141907 0.006 0.04
                                                                    }
                                                                  }
                                                                ]
                                                              }
                                                              Pose {
                                                                translation 0.036 0.145 -0.116
                                                                children [
                                                                  Shape {
                                                                    appearance USE METAL_APPEARANCE
                                                                    geometry Box {
                                                                      size 0.027 0.03 0.03
                                                                    }
                                                                  }
                                                                ]
                                                              }
                                                            ]
                                                          }
                                                        ]
                                                      }
                                                    ]
                                                    boundingObject Pose {
                                                      translation 0 0.0015 -0.019
                                                      children [
                                                        Shape {
                                                          appearance USE METAL_APPEARANCE
                                                          geometry Box {
                                                            size 0.315 0.05 0.045
                                                          }
                                                        }
                                                      ]
                                                    }
                                                    physics DEF LIFT_PHYSICS Physics {
                                                    }
                                                  }
                                                }
                                                Pose {
                                                  translation -0.135 0 -0.126
                                                  rotation 0.5773502691896258 -0.5773502691896258 -0.5773502691896258 2.094395
                                                  children [
                                                    DEF BASE_SHAPE_GROUP Group {
                                                      children [
                                                        Pose {
                                                          translation 0 0.176 -0.154
                                                          children [
                                                            DEF UPPER_BOX Shape {
                                                              appearance USE BLACK_APPEARANCE
                                                              geometry Box {
                                                                size 0.141092 0.0170038 0.043419
                                                              }
                                                            }
                                                          ]
                                                        }
                                                        Pose {
                                                          translation 0 0.075 -0.154
                                                          children [
                                                            USE UPPER_BOX
                                                          ]
                                                        }
                                                        Pose {
                                                          translation -0.06 0.126 -0.158
                                                          children [
                                                            DEF LEFT_BOX Shape {
                                                              appearance USE BLACK_APPEARANCE
                                                              geometry Box {
                                                                size 0.02 0.0875 0.035
                                                              }
                                                            }
                                                          ]
                                                        }
                                                        Pose {
                                                          translation 0.06 0.126 -0.158
                                                          children [
                                                            USE LEFT_BOX
                                                          ]
                                                        }
                                                        Pose {
                                                          translation 0 0.126 -0.158
                                                          children [
                                                            DEF CENTER_BOX Shape {
                                                              appearance USE BLACK_APPEARANCE
                                                              geometry Box {
                                                                size 0.044 0.1 0.0315
                                                              }
                                                            }
                                                          ]
                                                        }
                                                        Pose {
                                                          translation -0.037 0.126 -0.158
                                                          rotation 1 0 0 -1.570796
                                                          children [
                                                            DEF LEFT_CYLINDER Shape {
                                                              appearance USE METAL_APPEARANCE
                                                              geometry Cylinder {
                                                                height 0.1
                                                                radius 0.003
                                                              }
                                                            }
                                                          ]
                                                        }
                                                        Pose {
                                                          translation 0.037 0.126 -0.158
                                                          rotation 1 0 0 -1.570796
                                                          children [
                                                            USE LEFT_CYLINDER
                                                          ]
                                                        }
                                                      ]
                                                    }
                                                  ]
                                                }
                                              ]
                                              name "Pioneer3 gripper"
                                              model "Pioneer3 gripper"
                                              boundingObject Pose {
                                                translation 0.019 0 0
                                                children [
                                                  Box {
                                                    size 0.043 0.141 0.117
                                                  }
                                                ]
                                              }
                                              physics DEF BASE_PHYSICS Physics {
                                              }
                                            }
                                          ]
                                        }
                                      ]
                                      name "wrist_3_link"
                                      boundingObject Group {
                                        children [
                                          Pose {
                                            translation 0 0.07 0
                                            rotation 1 0 0 -1.57079632679
                                            children [
                                              Cylinder {
                                                height 0.048
                                                radius 0.038
                                              }
                                            ]
                                          }
                                          Pose {
                                            translation 0 0.09 0
                                            rotation 1 0 0 -1.57079632679
                                            children [
                                              Cylinder {
                                                height 0.018
                                                radius 0.032
                                              }
                                            ]
                                          }
                                        ]
                                      }
                                      physics Physics {
                                        density -1
                                        mass 0.365
                                        centerOfMass [
                                          0 0.071 0
                                        ]
                                      }
                                    }
                                  }
                                ]
                                name "wrist_2_link"
                                boundingObject Group {
                                  children [
                                    Pose {
                                      translation 0 -0.001 0.0995
                                      rotation 1 0 0 -1.57079632679
                                      children [
                                        Cylinder {
                                          height 0.108
                                          radius 0.04
                                        }
                                      ]
                                    }
                                    Pose {
                                      translation 0 -0.001 0.0676
                                      children [
                                        Cylinder {
                                          height 0.043
                                          radius 0.038
                                        }
                                      ]
                                    }
                                  ]
                                }
                                physics Physics {
                                  density -1
                                  mass 1.3
                                  centerOfMass [
                                    0 0 0.1
                                  ]
                                }
                              }
                            }
                          ]
                          name "wrist_1_link"
                          boundingObject Group {
                            children [
                              Pose {
                                translation 0 0.089 0
                                rotation 1 0 0 -1.57079632679
                                children [
                                  Cylinder {
                                    height 0.086
                                    radius 0.038
                                  }
                                ]
                              }
                              Pose {
                                translation 0 0.126 0
                                children [
                                  Cylinder {
                                    height 0.112
                                    radius 0.038
                                  }
                                ]
                              }
                            ]
                          }
                          physics Physics {
                            density -1
                            mass 1.37
                            centerOfMass [
                              0 0.127 0
                            ]
                          }
                        }
                      }
                    ]
                    name "forearm_link"
                    boundingObject Group {
                      children [
                        Pose {
                          translation 0 0 0.207
                          children [
                            Cylinder {
                              height 0.36
                              radius 0.038
                            }
                          ]
                        }
                        Pose {
                          translation 0 -0.001 0.39
                          rotation 1 0 0 -1.57079632679
                          children [
                            Cylinder {
                              height 0.109
                              radius 0.039
                            }
                          ]
                        }
                        Pose {
                          translation 0 0.06 0
                          rotation 1 0 0 1.57079632679
                          children [
                            Capsule {
                              height 0.05
                              radius 0.058
                              subdivision 16
                            }
                          ]
                        }
                        Pose {
                          translation 0 0 0.07
                          children [
                            Capsule {
                              height 0.1
                              radius 0.04
                              subdivision 16
                            }
                          ]
                        }
                      ]
                    }
                    physics Physics {
                      density -1
                      mass 2.846
                      centerOfMass [
                        0 0 0.15
                      ]
                    }
                  }
                }
              ]
              name "upper_arm_link"
              boundingObject Group {
                children [
                  Pose {
                    translation 0 0 0.22
                    children [
                      Cylinder {
                        height 0.407
                        radius 0.059
                      }
                    ]
                  }
                  Pose {
                    rotation 1 0 0 -1.57079632679
                    children [
                      Cylinder {
                        height 0.133
                        radius 0.059
                      }
                    ]
                  }
                  Pose {
                    translation 0 -0.005 0.424
                    rotation 1 0 0 -1.57079632679
                    children [
                      Cylinder {
                        height 0.149
                        radius 0.059
                      }
                    ]
                  }
                ]
              }
              physics Physics {
                density -1
                mass 8.058
                centerOfMass [
                  0 0 0.2125
                ]
              }
            }
          }
        ]
        name "shoulder_link"
        boundingObject Group {
          children [
            Pose {
              children [
                Cylinder {
                  height 0.135
                  radius 0.059
                }
              ]
            }
            Pose {
              translation 0 0.03 0
              rotation 1 0 0 -1.57079632679
              children [
                Cylinder {
                  height 0.093
                  radius 0.059
                }
              ]
            }
          ]
        }
        physics Physics {
          density -1
          mass 3.761
          centerOfMass [
            0 -0.02561 0.00193
          ]
        }
      }
    }
  ]
  name "UR5e"
  model "UR5e"
  boundingObject Pose {
    translation 0 0 0.05
    children [
      Cylinder {
        height 0.1
        radius 0.076
      }
    ]
  }
  controller "arm_controller"
  selfCollision TRUE
}
