#VRML_SIM R2025a utf8

EXTERNPROTO "https://raw.githubusercontent.com/cyberbotics/webots/R2025a/projects/objects/backgrounds/protos/TexturedBackground.proto"
EXTERNPROTO "https://raw.githubusercontent.com/cyberbotics/webots/R2025a/projects/objects/backgrounds/protos/TexturedBackgroundLight.proto"
EXTERNPROTO "https://raw.githubusercontent.com/cyberbotics/webots/R2025a/projects/objects/floors/protos/Floor.proto"
EXTERNPROTO "https://raw.githubusercontent.com/cyberbotics/webots/R2025a/projects/appearances/protos/CorrugatedMetal.proto"
EXTERNPROTO "https://raw.githubusercontent.com/cyberbotics/webots/R2025a/projects/objects/apartment_structure/protos/Ceiling.proto"
EXTERNPROTO "https://raw.githubusercontent.com/cyberbotics/webots/R2025a/projects/objects/apartment_structure/protos/Door.proto"
EXTERNPROTO "https://raw.githubusercontent.com/cyberbotics/webots/R2025a/projects/objects/apartment_structure/protos/DoorLever.proto"
EXTERNPROTO "https://raw.githubusercontent.com/cyberbotics/webots/R2025a/projects/objects/factory/valves/protos/LeverValve.proto"
EXTERNPROTO "https://raw.githubusercontent.com/cyberbotics/webots/R2025a/projects/objects/factory/pipes/protos/PipeSection.proto"
EXTERNPROTO "https://raw.githubusercontent.com/cyberbotics/webots/R2025a/projects/objects/factory/pipes/protos/LJoint.proto"
EXTERNPROTO "https://raw.githubusercontent.com/cyberbotics/webots/R2025a/projects/objects/factory/pipes/protos/TJoint.proto"
EXTERNPROTO "https://raw.githubusercontent.com/cyberbotics/webots/R2025a/projects/objects/factory/pallet/protos/WoodenPalletStack.proto"
EXTERNPROTO "../protos/WoodenBox.proto"
EXTERNPROTO "../protos/QRBox.proto"
EXTERNPROTO "https://raw.githubusercontent.com/cyberbotics/webots/R2025a/projects/appearances/protos/OsbWood.proto"
EXTERNPROTO "https://raw.githubusercontent.com/cyberbotics/webots/R2025a/projects/appearances/protos/BrushedAluminium.proto"
EXTERNPROTO "https://raw.githubusercontent.com/cyberbotics/webots/R2025a/projects/objects/floors/protos/RectangleArena.proto"
EXTERNPROTO "https://raw.githubusercontent.com/cyberbotics/webots/R2025a/projects/appearances/protos/Parquetry.proto"
EXTERNPROTO "https://raw.githubusercontent.com/cyberbotics/webots/R2025a/projects/objects/factory/containers/protos/MetalStorageBox.proto"

WorldInfo {
  title "Pick and Place"
  window "pick_and_place"
  basicTimeStep 16
  defaultDamping Damping {
  }
  contactProperties [
    ContactProperties {
      material2 "box"
      coulombFriction [
        10
      ]
    }
  ]
}
Viewpoint {
  orientation -0.2276141862030795 0.4247405266623354 0.876234710137479 1.0977977614577288
  position -0.6340720564104743 -1.6214962020390369 1.9166940434257977
  exposure 1.5
}
TexturedBackground {
  texture "factory"
}
TexturedBackgroundLight {
  texture "factory"
  castShadows FALSE
}
SpotLight {
  attenuation 0 0 1
  beamWidth 0.7
  intensity 10
  location 0 0 4
  castShadows TRUE
}
Floor {
  rotation 0 0 1 -1.5707963267948966
  size 12 12
  tileSize 1 1
  appearance PBRAppearance {
    baseColorMap ImageTexture {
      url [
        "../textures/concrete.jpg"
      ]
    }
    roughness 1
    metalness 0
  }
}
MetalStorageBox {
  translation 0.430001 1.74 0
  rotation 0 0 1 1.5708
}
RectangleArena {
  translation -0.43 0.83 0.01
  floorAppearance Parquetry {
    type "dark strip"
    colorOverride 0 0 1
  }
}
QRBox {
  hidden linearVelocity_0 -3.5662032155222686e-07 0.09964408487901825 3.0790649946842794e-05
  hidden angularVelocity_0 -1.8611887053486077e-05 -6.446678489797008e-09 5.449466710728185e-10
  translation 1.040739864039687 0.21998460706142806 0.2143629268097453
  rotation 0.9115049143769177 -0.41128918179964247 1.1440968199692085e-06 3.1415871742091266
  name "C"
  color 1 0.6 0
  qrTexture [
    "../textures/qr2.png"
  ]
}
QRBox {
  hidden linearVelocity_0 -1.2027097770291844e-08 0.0996420341172087 1.529174139826809e-05
  hidden angularVelocity_0 6.341638573957642e-05 1.3783841211069095e-05 4.1811100019394855e-10
  translation 1.22331568157611 0.5209100417418727 0.21436107696790258
  rotation -0.05913948178933283 0.7058731287660086 0.7058651767722889 -3.023450983459123
  name "B"
  color 1 0.6 0
  qrTexture [
    "../textures/qr1.png"
  ]
}
DEF WALL Solid {
  translation 0 6 2.5
  rotation 1 0 0 1.5708
  children [
    DEF WALL_SHAPE Shape {
      appearance CorrugatedMetal {
        textureTransform TextureTransform {
          scale 2 2
        }
      }
      geometry Plane {
        size 12 5
      }
      castShadows FALSE
    }
  ]
  boundingObject USE WALL_SHAPE
}
DEF WALL Solid {
  translation 6 0 2.5
  rotation -0.5773509358508296 0.5773469358512743 0.5773529358506075 -2.094395307179586
  children [
    USE WALL_SHAPE
  ]
  name "solid(1)"
  boundingObject USE WALL_SHAPE
}
DEF WALL Solid {
  translation 0 -6 2.5
  rotation 3.808301514364728e-06 0.7071082811804253 0.7071052811792324 3.14159
  children [
    USE WALL_SHAPE
  ]
  name "solid(2)"
  boundingObject USE WALL_SHAPE
}
DEF WALL Solid {
  translation -6 0 2.5
  rotation -0.5773509358554485 -0.5773489358556708 -0.5773509358554485 -2.094395307179586
  children [
    USE WALL_SHAPE
  ]
  name "solid(3)"
  boundingObject USE WALL_SHAPE
}
Ceiling {
  translation 0 0 5
  size 12 12
  castShadows FALSE
}
Door {
  translation -2.45 5.96 0
  rotation 0 0 -1 1.5708
  size 0.01 1.2 2
  canBeOpen FALSE
  doorHandle DoorLever {
    translation 0 0 0.045
    mass 0
    hasStaticParent TRUE
    castShadows FALSE
  }
  castShadows FALSE
}
DEF PIPES Pose {
  rotation 0 0 1 -1.57
  children [
    LeverValve {
      hidden position_0_0 -1.1284963257221409e-06
      hidden translation_1 0 3.8569955506330676e-08 -3.7202879665798605e-14
      hidden rotation_1 -1 0 0 1.9288803488355914e-06
      hidden linearVelocity_1 1.4549421669243055e-10 7.783754084015861e-07 -2.0828893543650577e-08
      hidden angularVelocity_1 -4.08566927750257e-06 7.63152065343923e-10 -4.659946139958155e-11
      translation 0.50999991 -5.83 1
      rotation 0 0 1 1.5708
      scale 1 1 1
    }
    PipeSection {
      translation 2.11 -5.86 0.96000003
      rotation 0.7071067811860158 0 0.7071067811860158 -3.1415853071795863
      height 3
      radius 0.07
    }
    PipeSection {
      translation -2.81 -5.86 0.9600001
      rotation 0.7071067811860158 0 0.7071067811860158 -3.1415853071795863
      name "pipe section(1)"
      height 6.4
      radius 0.07
    }
    PipeSection {
      translation -4.39 -5.87 3.83
      rotation 0.7071067811860158 0 0.7071067811860158 -3.1415853071795863
      name "pipe section(2)"
      height 3.3
      radius 0.07
    }
    PipeSection {
      translation -1.63 -5.86 0.65
      rotation 0.7071067811860158 0 0.7071067811860158 -3.1415853071795863
      name "pipe section(3)"
      height 8.8
      radius 0.07
    }
    PipeSection {
      translation 3.857 -5.86 0.34
      rotation 0 0 -1 -1.5707953071795862
      name "pipe section(4)"
      height 0.7
      radius 0.07
    }
    PipeSection {
      translation 3.037 -5.86 0.19
      rotation 0 0 -1 -1.5707953071795862
      name "pipe section(5)"
      height 0.4
      radius 0.07
    }
    PipeSection {
      translation -2.443 -5.84 2.37
      rotation 0 0 -1 -1.5707953071795862
      name "pipe section(6)"
      height 2.4
      radius 0.07
    }
    LJoint {
      translation 3.74 -5.8610001 0.85599996
      rotation 0 1 0 3.14159
      scale 2.4 2.4 2.4
    }
    LJoint {
      translation 2.93 -5.8610001 0.54599994
      rotation 0 1 0 3.14159
      name "L joint pipe(1)"
      scale 2.4 2.4 2.4
    }
    LJoint {
      translation -2.55 -5.845 3.7259999
      rotation 0 1 0 3.14159
      name "L joint pipe(2)"
      scale 2.4 2.4 2.4
    }
    TJoint {
      translation -2.44 -5.843 1.0259999
      rotation 0 1 0 3.14159
      scale 2.4 2.4 2.4
    }
  ]
}
WoodenPalletStack {
  translation 3.51824 5.0701 0.0986936
  rotation 0 0 1 -0.523595307179586
}
WoodenPalletStack {
  translation 5.0506856 4.3236115 0
  rotation 0 0 -1 1.0472
  name "wooden pallet stack(1)"
  palletNumber 2
}
WoodenBox {
  translation 5.0461957 -2.6920662 0.3
  rotation 0 0 1 -1.5707963267948966
}
WoodenBox {
  translation 5.0297142 -3.3127088 0.3
  rotation 0 0 1 -1.5707963267948966
  name "wooden box(1)"
}
WoodenBox {
  translation 5.0890438 -2.0668732 0.3
  rotation 0 0 -1 1.571421196638078
  name "wooden box(2)"
}
WoodenBox {
  translation 5.0324568 -3.0679729 0.9
  rotation 0.004999875004687304 0.004999875004687304 -0.9999750009374608 1.570821326586566
  name "wooden box(3)"
}
QRBox {
  hidden linearVelocity_0 -2.6309071962388476e-06 0.09965455058790426 0.00017760739342514826
  hidden angularVelocity_0 -0.0004371816919828851 -9.097546591333424e-05 1.3611296408829023e-09
  translation 1.1309199543640724 0.3584626593977779 0.21435219249761395
  rotation 1.799488307621188e-06 -1.0823569368309725e-05 0.9999999999398062 -2.9122876960946598
  name "A"
  color 1 0.6 0
  qrTexture [
    "../textures/qr.png"
  ]
}
DEF CONVEYOR_BELT Robot {
  translation 1.08 -0.725002 0.15
  children [
    Track {
      translation -2.696547654945647e-06 0.1499989926163805 0.014397324536251893
      rotation -4.582030052968532e-06 4.749283689497738e-06 0.9999999999782245 1.5707999010110005
      children [
        DEF BELT Shape {
          appearance PBRAppearance {
            baseColorMap ImageTexture {
              url [
                "https://raw.githubusercontent.com/cyberbotics/webots/R2025a/projects/samples/robotbenchmark/pick_and_place/worlds/textures/conveyor_belt_rubber.jpg"
              ]
            }
            roughness 1
            metalness 0
            textureTransform TextureTransform {
              rotation 1.5708
              scale 0.5 2
              translation -0.20587199999875286 0
            }
          }
          geometry Box {
            size 2.78 0.5 0.05
          }
        }
      ]
      boundingObject USE BELT
      physics Physics {
      }
      device [
        LinearMotor {
          name "belt motor"
        }
      ]
      textureAnimation 0.27 0
      linearVelocity 7.360394777430658e-11 1.1309679255713376e-08 -6.363273556585395e-06
      angularVelocity -3.178568232749654e-07 1.3576068833278665e-09 5.418212216450808e-10
    }
    DEF CYL1 Pose {
      translation 0 1.28 0
      rotation 0 1 0 -1.570796
      children [
        DEF CYL Shape {
          appearance BrushedAluminium {
          }
          geometry Cylinder {
            height 0.5
            radius 0.03
          }
        }
      ]
    }
    DEF CYL2 Pose {
      translation 0 1.34 0
      rotation 0 1 0 -1.570796
      children [
        USE CYL
      ]
    }
    DEF CYL3 Pose {
      translation 0 1.4 0
      rotation 0 1 0 -1.570796
      children [
        USE CYL
      ]
    }
    DEF CYL4 Pose {
      translation 0 1.46 0
      rotation 0 1 0 -1.570796
      children [
        USE CYL
      ]
    }
    DEF CYL5 Pose {
      translation 0 1.52 0
      rotation 0 1 0 -1.570796
      children [
        USE CYL
      ]
    }
    DEF LEFT Pose {
      translation -0.26 0.31 0.01
      children [
        Shape {
          appearance BrushedAluminium {
          }
          geometry Box {
            size 0.02 3.1 0.1
          }
        }
      ]
    }
    DEF RIGHT Pose {
      translation 0.26 0.31 0.01
      children [
        Shape {
          appearance BrushedAluminium {
          }
          geometry Box {
            size 0.02 3.1 0.1
          }
        }
      ]
    }
    DEF BACK Pose {
      translation 0 1.87 0.01
      rotation 0 0 1 1.57079
      children [
        Shape {
          appearance BrushedAluminium {
          }
          geometry Box {
            size 0.02 0.54 0.1
          }
        }
      ]
    }
    DEF BOTTOM Pose {
      translation 0 1.69 -0.01
      rotation 0 0 1 1.5708
      children [
        Shape {
          appearance BrushedAluminium {
          }
          geometry Box {
            size 0.34 0.54 0.01
          }
        }
      ]
    }
    DEF FOOT1 Pose {
      translation 0.22 1.78 -0.1
      rotation 0 0 1 -1.5708
      children [
        Shape {
          appearance BrushedAluminium {
          }
          geometry Cylinder {
            height 0.12
            radius 0.03
          }
        }
      ]
    }
    DEF FOOT2 Pose {
      translation -0.22 1.78 -0.1
      rotation 0 0 1 -1.5708
      children [
        Shape {
          appearance BrushedAluminium {
          }
          geometry Cylinder {
            height 0.12
            radius 0.03
          }
        }
      ]
    }
    DEF FOOT3 Pose {
      translation -0.220005 0.159999 -0.1
      rotation 0 0 1 -1.5708
      children [
        Shape {
          appearance BrushedAluminium {
          }
          geometry Cylinder {
            height 0.12
            radius 0.03
          }
        }
      ]
    }
    DEF FOOT4 Pose {
      translation 0.220005 0.159999 -0.1
      rotation 0 0 1 -1.5708
      children [
        Shape {
          appearance BrushedAluminium {
          }
          geometry Cylinder {
            height 0.12
            radius 0.03
          }
        }
      ]
    }
    Receiver {
      channel 1
    }
  ]
  name "conveyor belt"
  boundingObject Group {
    children [
      USE CYL1
      USE CYL2
      USE CYL3
      USE CYL4
      USE CYL5
      USE LEFT
      USE RIGHT
      USE BOTTOM
      USE BACK
      USE FOOT1
      USE FOOT2
      USE FOOT3
      USE FOOT4
    ]
  }
  controller "belt_controller"
}
Robot {
  translation 0.5306991424560397 0.21035688617912274 0.010244939960079136
  rotation -6.305884207424503e-11 4.657855119747465e-10 1 1.5060317110590409
  children [
    HingeJoint {
      jointParameters HingeJointParameters {
        position 973.7530668954861
        axis 0 0 1
      }
      device [
        RotationalMotor {
          name "plate_motor"
          maxVelocity 6.28
          maxTorque 20
          sound ""
        }
        PositionSensor {
          name "plate_sensor"
        }
      ]
      endPoint Solid {
        translation 5.226171037136459e-08 -3.718813056752639e-08 0.11997247509779098
        rotation -5.039675479227783e-07 -4.8835168991508925e-06 -0.9999999999879485 0.14065571735189517
        children [
          Shape {
            appearance OsbWood {
            }
            geometry Cylinder {
              height 0.02
              radius 0.15
            }
          }
        ]
        name "plate_disc"
        contactMaterial "sticky_plate"
        boundingObject Cylinder {
          height 0.02
          radius 0.15
        }
        physics Physics {
          density -1
          mass 0.5
        }
        linearVelocity 1.3278721317888808e-15 3.7041285731464443e-16 -4.787534436520557e-08
        angularVelocity 2.4251218434479976e-16 -2.725533503122532e-16 6.645062169606876e-19
      }
    }
    Receiver {
      channel 1
    }
    Emitter {
      channel 2
    }
  ]
  name "rotating_plate"
  boundingObject Cylinder {
    height 0.001
    radius 0.14
  }
  physics Physics {
    density -1
    mass 0.8
  }
  controller "plate_controller"
  synchronization FALSE
  linearVelocity -1.2949656439810204e-18 -1.194125635362217e-18 5.079546862331591e-10
  angularVelocity 2.504426239056949e-15 -2.697005736341158e-15 6.643509272336481e-19
}
Robot {
  translation 0.39 1.02 0
  rotation 0 0 1 -1.5707953071795862
  children [
    Emitter {
      channel 1
    }
    Receiver {
      channel 2
    }
    Camera {
      translation 1.11805 0.15283 0.18
      rotation 1.32679e-06 1.59084e-06 1 3.14159
      name "side_camera"
      fieldOfView 1
      width 1280
      height 720
      far 100
      recognition Recognition {
      }
    }
    Camera {
      translation 0.0942022 0.688368 0.690308
      rotation 0.6597579156185216 0.018277297662376818 -0.7512559039161452 -3.1291253071795864
      name "top_camera"
      fieldOfView 1
      width 1280
      height 720
      far 100
      recognition Recognition {
      }
    }
    Pose {
      translation -0.0467 0.047 0.0252
      rotation 1 0 0 -3.1415923071795864
      children [
        DEF SCREW Group {
          children [
            Transform {
              scale 1.1 1.1 1.1
              children [
                Shape {
                  appearance PBRAppearance {
                    baseColorMap ImageTexture {
                      url [
                        "https://raw.githubusercontent.com/cyberbotics/webots/R2025a/projects/appearances/protos/textures/old_steel/old_steel_base_color.jpg"
                      ]
                    }
                    roughnessMap ImageTexture {
                      url [
                        "https://raw.githubusercontent.com/cyberbotics/webots/R2025a/projects/appearances/protos/textures/old_steel/old_steel_roughness.jpg"
                      ]
                    }
                    metalnessMap ImageTexture {
                      url [
                        "https://raw.githubusercontent.com/cyberbotics/webots/R2025a/projects/appearances/protos/textures/old_steel/old_steel_metalness.jpg"
                      ]
                    }
                    normalMap ImageTexture {
                      url [
                        "https://raw.githubusercontent.com/cyberbotics/webots/R2025a/projects/appearances/protos/textures/old_steel/old_steel_normal.jpg"
                      ]
                    }
                  }
                  geometry Mesh {
                    url [
                      "https://raw.githubusercontent.com/cyberbotics/webots/R2025a/projects/robots/universal_robots/protos/UR5e/meshes/screw.obj"
                    ]
                  }
                }
              ]
            }
            DEF CYLINDER Pose {
              translation 0 0 0.02
              children [
                Shape {
                  appearance PBRAppearance {
                    baseColorMap ImageTexture {
                      url [
                        "https://raw.githubusercontent.com/cyberbotics/webots/R2025a/projects/appearances/protos/textures/screw_thread/screw_thread_base_color.jpg"
                      ]
                    }
                    roughnessMap ImageTexture {
                      url [
                        "https://raw.githubusercontent.com/cyberbotics/webots/R2025a/projects/appearances/protos/textures/screw_thread/screw_thread_roughness.jpg"
                      ]
                    }
                    normalMap ImageTexture {
                      url [
                        "https://raw.githubusercontent.com/cyberbotics/webots/R2025a/projects/appearances/protos/textures/screw_thread/screw_thread_normal.jpg"
                      ]
                    }
                    occlusionMap ImageTexture {
                      url [
                        "https://raw.githubusercontent.com/cyberbotics/webots/R2025a/projects/appearances/protos/textures/screw_thread/screw_thread_occlusion.jpg"
                      ]
                    }
                    textureTransform TextureTransform {
                      rotation 1.5708
                      scale 1.6 2
                    }
                  }
                  geometry Cylinder {
                    height 0.04
                    radius 0.0044
                  }
                }
              ]
            }
          ]
        }
      ]
    }
    Pose {
      translation -0.0467 -0.047 0.0252
      rotation 1 0 0 -3.1415923071795864
      children [
        USE SCREW
      ]
    }
    Pose {
      translation 0.0464 -0.047 0.0252
      rotation 1 0 0 -3.1415923071795864
      children [
        USE SCREW
      ]
    }
    Pose {
      translation 0.0464 0.047 0.0252
      rotation 1 0 0 -3.1415923071795864
      children [
        USE SCREW
      ]
    }
    Shape {
      appearance DEF METAL_APPEARANCE PBRAppearance {
        baseColor 0.6 0.6 0.6
        roughness 0.7
      }
      geometry Mesh {
        url [
          "https://raw.githubusercontent.com/cyberbotics/webots/R2025a/projects/robots/universal_robots/protos/UR5e/meshes/base_link_0.obj"
        ]
      }
    }
    Shape {
      appearance DEF JOINT_APPEARANCE PBRAppearance {
        baseColor 0 0 0
        roughness 1
        metalness 0
      }
      geometry Mesh {
        url [
          "https://raw.githubusercontent.com/cyberbotics/webots/R2025a/projects/robots/universal_robots/protos/UR5e/meshes/base_link_1.obj"
        ]
      }
    }
    HingeJoint {
      jointParameters HingeJointParameters {
        position 7.267401292704012e-07
        axis 0 0 1
        anchor 0 0 0.163
      }
      device [
        RotationalMotor {
          name "shoulder_pan_joint"
          maxVelocity 3.14
          minPosition -6.28318530718
          maxPosition 6.28318530718
          maxTorque 150
        }
        PositionSensor {
          name "shoulder_pan_joint_sensor"
        }
      ]
      endPoint Solid {
        translation 0 0 0.163
        rotation 0 0 1 7.269567798167786e-07
        children [
          Shape {
            appearance USE METAL_APPEARANCE
            geometry Mesh {
              url [
                "https://raw.githubusercontent.com/cyberbotics/webots/R2025a/projects/robots/universal_robots/protos/UR5e/meshes/shoulder_link_0.obj"
              ]
            }
          }
          Shape {
            appearance USE JOINT_APPEARANCE
            geometry Mesh {
              url [
                "https://raw.githubusercontent.com/cyberbotics/webots/R2025a/projects/robots/universal_robots/protos/UR5e/meshes/shoulder_link_1.obj"
              ]
            }
          }
          Shape {
            appearance PBRAppearance {
              baseColor 0.4902 0.678431 0.8
              roughness 0.4
              metalness 0
              normalMap ImageTexture {
                url [
                  "https://raw.githubusercontent.com/cyberbotics/webots/R2025a/projects/robots/universal_robots/protos/UR5e/textures/normal_0.jpg"
                ]
              }
              occlusionMap ImageTexture {
                url [
                  "https://raw.githubusercontent.com/cyberbotics/webots/R2025a/projects/robots/universal_robots/protos/UR5e/textures/occlusion_0.jpg"
                ]
              }
            }
            geometry Mesh {
              url [
                "https://raw.githubusercontent.com/cyberbotics/webots/R2025a/projects/robots/universal_robots/protos/UR5e/meshes/shoulder_link_2.obj"
              ]
            }
          }
          Shape {
            appearance DEF SCREW_APPEARANCE PBRAppearance {
            }
            geometry Mesh {
              url [
                "https://raw.githubusercontent.com/cyberbotics/webots/R2025a/projects/robots/universal_robots/protos/UR5e/meshes/shoulder_link_3.obj"
              ]
            }
          }
          HingeJoint {
            jointParameters HingeJointParameters {
              position -1.5707999514479103
              axis 0 1 0
              anchor 0 0.138 0
            }
            device [
              RotationalMotor {
                name "shoulder_lift_joint"
                maxVelocity 3.14
                minPosition -6.28318530718
                maxPosition 6.28318530718
                maxTorque 150
              }
              PositionSensor {
                name "shoulder_lift_joint_sensor"
              }
            ]
            endPoint Solid {
              translation 0 0.138 0
              rotation 0 -1 0 3.949791632736817e-06
              children [
                Shape {
                  appearance PBRAppearance {
                    baseColor 0.4902 0.678431 0.8
                    roughness 0.4
                    metalness 0
                    normalMap ImageTexture {
                      url [
                        "https://raw.githubusercontent.com/cyberbotics/webots/R2025a/projects/robots/universal_robots/protos/UR5e/textures/normal_1.jpg"
                      ]
                    }
                    occlusionMap ImageTexture {
                      url [
                        "https://raw.githubusercontent.com/cyberbotics/webots/R2025a/projects/robots/universal_robots/protos/UR5e/textures/occlusion_1.jpg"
                      ]
                    }
                  }
                  geometry Mesh {
                    url [
                      "https://raw.githubusercontent.com/cyberbotics/webots/R2025a/projects/robots/universal_robots/protos/UR5e/meshes/upper_arm_link_0.obj"
                    ]
                  }
                }
                Shape {
                  appearance USE SCREW_APPEARANCE
                  geometry Mesh {
                    url [
                      "https://raw.githubusercontent.com/cyberbotics/webots/R2025a/projects/robots/universal_robots/protos/UR5e/meshes/upper_arm_link_1.obj"
                    ]
                  }
                }
                Shape {
                  appearance USE METAL_APPEARANCE
                  geometry Mesh {
                    url [
                      "https://raw.githubusercontent.com/cyberbotics/webots/R2025a/projects/robots/universal_robots/protos/UR5e/meshes/upper_arm_link_2.obj"
                    ]
                  }
                }
                Shape {
                  appearance USE JOINT_APPEARANCE
                  geometry Mesh {
                    url [
                      "https://raw.githubusercontent.com/cyberbotics/webots/R2025a/projects/robots/universal_robots/protos/UR5e/meshes/upper_arm_link_3.obj"
                    ]
                  }
                }
                Shape {
                  appearance PBRAppearance {
                    baseColor 0.4902 0.678431 0.8
                    roughness 0.4
                    metalness 0
                    normalMap ImageTexture {
                      url [
                        "https://raw.githubusercontent.com/cyberbotics/webots/R2025a/projects/robots/universal_robots/protos/UR5e/textures/normal_2.jpg"
                      ]
                    }
                    occlusionMap ImageTexture {
                      url [
                        "https://raw.githubusercontent.com/cyberbotics/webots/R2025a/projects/robots/universal_robots/protos/UR5e/textures/occlusion_2.jpg"
                      ]
                    }
                  }
                  geometry Mesh {
                    url [
                      "https://raw.githubusercontent.com/cyberbotics/webots/R2025a/projects/robots/universal_robots/protos/UR5e/meshes/upper_arm_link_4.obj"
                    ]
                  }
                }
                Shape {
                  appearance USE SCREW_APPEARANCE
                  geometry Mesh {
                    url [
                      "https://raw.githubusercontent.com/cyberbotics/webots/R2025a/projects/robots/universal_robots/protos/UR5e/meshes/upper_arm_link_5.obj"
                    ]
                  }
                }
                Shape {
                  appearance DEF METAL_APPEARANCE_LIGHT PBRAppearance {
                    roughness 0.7
                  }
                  geometry Mesh {
                    url [
                      "https://raw.githubusercontent.com/cyberbotics/webots/R2025a/projects/robots/universal_robots/protos/UR5e/meshes/upper_arm_link_6.obj"
                    ]
                  }
                }
                Shape {
                  appearance USE JOINT_APPEARANCE
                  geometry Mesh {
                    url [
                      "https://raw.githubusercontent.com/cyberbotics/webots/R2025a/projects/robots/universal_robots/protos/UR5e/meshes/upper_arm_link_7.obj"
                    ]
                  }
                }
                Shape {
                  appearance USE METAL_APPEARANCE
                  geometry Mesh {
                    url [
                      "https://raw.githubusercontent.com/cyberbotics/webots/R2025a/projects/robots/universal_robots/protos/UR5e/meshes/upper_arm_link_8.obj"
                    ]
                  }
                }
                Shape {
                  appearance USE JOINT_APPEARANCE
                  geometry Mesh {
                    url [
                      "https://raw.githubusercontent.com/cyberbotics/webots/R2025a/projects/robots/universal_robots/protos/UR5e/meshes/upper_arm_link_9.obj"
                    ]
                  }
                }
                HingeJoint {
                  jointParameters HingeJointParameters {
                    position -6.573851157229343e-06
                    axis 0 1 0
                    anchor 0 -0.131 0.425
                  }
                  device [
                    RotationalMotor {
                      name "elbow_joint"
                      maxVelocity 3.14
                      minPosition -3.14159265359
                      maxPosition 3.14159265359
                      maxTorque 150
                    }
                    PositionSensor {
                      name "elbow_joint_sensor"
                    }
                  ]
                  endPoint Solid {
                    translation 0 -0.131 0.425
                    rotation 0 -1 0 6.573827590450498e-06
                    children [
                      Shape {
                        appearance USE METAL_APPEARANCE
                        geometry Mesh {
                          url [
                            "https://raw.githubusercontent.com/cyberbotics/webots/R2025a/projects/robots/universal_robots/protos/UR5e/meshes/forearm_link_0.obj"
                          ]
                        }
                      }
                      Shape {
                        appearance USE METAL_APPEARANCE
                        geometry Mesh {
                          url [
                            "https://raw.githubusercontent.com/cyberbotics/webots/R2025a/projects/robots/universal_robots/protos/UR5e/meshes/forearm_link_1.obj"
                          ]
                        }
                      }
                      Shape {
                        appearance USE JOINT_APPEARANCE
                        geometry Mesh {
                          url [
                            "https://raw.githubusercontent.com/cyberbotics/webots/R2025a/projects/robots/universal_robots/protos/UR5e/meshes/forearm_link_2.obj"
                          ]
                        }
                      }
                      Shape {
                        appearance USE METAL_APPEARANCE_LIGHT
                        geometry Mesh {
                          url [
                            "https://raw.githubusercontent.com/cyberbotics/webots/R2025a/projects/robots/universal_robots/protos/UR5e/meshes/forearm_link_3.obj"
                          ]
                        }
                      }
                      Shape {
                        appearance USE JOINT_APPEARANCE
                        geometry Mesh {
                          url [
                            "https://raw.githubusercontent.com/cyberbotics/webots/R2025a/projects/robots/universal_robots/protos/UR5e/meshes/forearm_link_4.obj"
                          ]
                        }
                      }
                      Shape {
                        appearance PBRAppearance {
                          baseColor 0.4902 0.678431 0.8
                          roughness 0.4
                          metalness 0
                          normalMap ImageTexture {
                            url [
                              "https://raw.githubusercontent.com/cyberbotics/webots/R2025a/projects/robots/universal_robots/protos/UR5e/textures/normal_3.jpg"
                            ]
                          }
                          occlusionMap ImageTexture {
                            url [
                              "https://raw.githubusercontent.com/cyberbotics/webots/R2025a/projects/robots/universal_robots/protos/UR5e/textures/occlusion_3.jpg"
                            ]
                          }
                        }
                        geometry Mesh {
                          url [
                            "https://raw.githubusercontent.com/cyberbotics/webots/R2025a/projects/robots/universal_robots/protos/UR5e/meshes/forearm_link_5.obj"
                          ]
                        }
                      }
                      Shape {
                        appearance USE SCREW_APPEARANCE
                        geometry Mesh {
                          url [
                            "https://raw.githubusercontent.com/cyberbotics/webots/R2025a/projects/robots/universal_robots/protos/UR5e/meshes/forearm_link_6.obj"
                          ]
                        }
                      }
                      Shape {
                        appearance USE JOINT_APPEARANCE
                        geometry Mesh {
                          url [
                            "https://raw.githubusercontent.com/cyberbotics/webots/R2025a/projects/robots/universal_robots/protos/UR5e/meshes/forearm_link_7.obj"
                          ]
                        }
                      }
                      HingeJoint {
                        jointParameters HingeJointParameters {
                          position -1.5707999855957664
                          axis 0 1 0
                          anchor 0 0 0.392
                        }
                        device [
                          RotationalMotor {
                            name "wrist_1_joint"
                            maxVelocity 6.28
                            minPosition -6.28318530718
                            maxPosition 6.28318530718
                            maxTorque 28
                          }
                          PositionSensor {
                            name "wrist_1_joint_sensor"
                          }
                        ]
                        endPoint Solid {
                          translation 0 0 0.392
                          rotation 0 -1 0 3.9847165029628385e-06
                          children [
                            Shape {
                              appearance USE METAL_APPEARANCE
                              geometry Mesh {
                                url [
                                  "https://raw.githubusercontent.com/cyberbotics/webots/R2025a/projects/robots/universal_robots/protos/UR5e/meshes/wrist_1_link_0.obj"
                                ]
                              }
                            }
                            Shape {
                              appearance PBRAppearance {
                                baseColor 0.4902 0.678431 0.8
                                roughness 0.4
                                metalness 0
                                normalMap ImageTexture {
                                  url [
                                    "https://raw.githubusercontent.com/cyberbotics/webots/R2025a/projects/robots/universal_robots/protos/UR5e/textures/normal_4.jpg"
                                  ]
                                }
                                occlusionMap ImageTexture {
                                  url [
                                    "https://raw.githubusercontent.com/cyberbotics/webots/R2025a/projects/robots/universal_robots/protos/UR5e/textures/occlusion_4.jpg"
                                  ]
                                }
                              }
                              geometry Mesh {
                                url [
                                  "https://raw.githubusercontent.com/cyberbotics/webots/R2025a/projects/robots/universal_robots/protos/UR5e/meshes/wrist_1_link_1.obj"
                                ]
                              }
                            }
                            Shape {
                              appearance USE SCREW_APPEARANCE
                              geometry Mesh {
                                url [
                                  "https://raw.githubusercontent.com/cyberbotics/webots/R2025a/projects/robots/universal_robots/protos/UR5e/meshes/wrist_1_link_2.obj"
                                ]
                              }
                            }
                            Shape {
                              appearance USE JOINT_APPEARANCE
                              geometry Mesh {
                                url [
                                  "https://raw.githubusercontent.com/cyberbotics/webots/R2025a/projects/robots/universal_robots/protos/UR5e/meshes/wrist_1_link_3.obj"
                                ]
                              }
                            }
                            HingeJoint {
                              jointParameters HingeJointParameters {
                                position 1.9725381388289723e-06
                                axis 0 0 1
                                anchor 0 0.127 0
                              }
                              device [
                                RotationalMotor {
                                  name "wrist_2_joint"
                                  maxVelocity 6.28
                                  minPosition -6.28318530718
                                  maxPosition 6.28318530718
                                  maxTorque 28
                                }
                                PositionSensor {
                                  name "wrist_2_joint_sensor"
                                }
                              ]
                              endPoint Solid {
                                translation 0 0.127 0
                                rotation 0 0 1 1.9725895814148884e-06
                                children [
                                  Shape {
                                    appearance USE METAL_APPEARANCE
                                    geometry Mesh {
                                      url [
                                        "https://raw.githubusercontent.com/cyberbotics/webots/R2025a/projects/robots/universal_robots/protos/UR5e/meshes/wrist_2_link_0.obj"
                                      ]
                                    }
                                  }
                                  Shape {
                                    appearance PBRAppearance {
                                      baseColor 0.4902 0.678431 0.8
                                      roughness 0.4
                                      metalness 0
                                      normalMap ImageTexture {
                                        url [
                                          "https://raw.githubusercontent.com/cyberbotics/webots/R2025a/projects/robots/universal_robots/protos/UR5e/textures/normal_5.jpg"
                                        ]
                                      }
                                      occlusionMap ImageTexture {
                                        url [
                                          "https://raw.githubusercontent.com/cyberbotics/webots/R2025a/projects/robots/universal_robots/protos/UR5e/textures/occlusion_5.jpg"
                                        ]
                                      }
                                    }
                                    geometry Mesh {
                                      url [
                                        "https://raw.githubusercontent.com/cyberbotics/webots/R2025a/projects/robots/universal_robots/protos/UR5e/meshes/wrist_2_link_1.obj"
                                      ]
                                    }
                                  }
                                  Shape {
                                    appearance USE SCREW_APPEARANCE
                                    geometry Mesh {
                                      url [
                                        "https://raw.githubusercontent.com/cyberbotics/webots/R2025a/projects/robots/universal_robots/protos/UR5e/meshes/wrist_2_link_2.obj"
                                      ]
                                    }
                                  }
                                  Shape {
                                    appearance USE JOINT_APPEARANCE
                                    geometry Mesh {
                                      url [
                                        "https://raw.githubusercontent.com/cyberbotics/webots/R2025a/projects/robots/universal_robots/protos/UR5e/meshes/wrist_2_link_3.obj"
                                      ]
                                    }
                                  }
                                  HingeJoint {
                                    jointParameters HingeJointParameters {
                                      position -1.9724258625985355e-06
                                      axis 0 1 0
                                      anchor 0 0 0.1
                                    }
                                    device [
                                      RotationalMotor {
                                        name "wrist_3_joint"
                                        maxVelocity 6.28
                                        minPosition -6.28318530718
                                        maxPosition 6.28318530718
                                        maxTorque 28
                                      }
                                      PositionSensor {
                                        name "wrist_3_joint_sensor"
                                      }
                                    ]
                                    endPoint Solid {
                                      translation 0 0 0.1
                                      rotation 0 -1 0 1.972364438506957e-06
                                      children [
                                        Shape {
                                          appearance USE METAL_APPEARANCE
                                          geometry Mesh {
                                            url [
                                              "https://raw.githubusercontent.com/cyberbotics/webots/R2025a/projects/robots/universal_robots/protos/UR5e/meshes/wrist_3_link_0.obj"
                                            ]
                                          }
                                        }
                                        Pose {
                                          translation 0 0.1 0
                                          children [
                                            DEF GRIPPER_BASE Solid {
                                              rotation 0 0 1 1.5708
                                              children [
                                                DEF LIFT_SLIDER SliderJoint {
                                                  jointParameters JointParameters {
                                                    position 8.04990710213945e-06
                                                    axis 0 0 -1
                                                  }
                                                  device [
                                                    LinearMotor {
                                                      name "lift motor"
                                                      minPosition -0.05
                                                      maxPosition 0.05
                                                    }
                                                  ]
                                                  endPoint DEF LIFT Solid {
                                                    translation 0.042500004946005365 -7.747869013030595e-10 -8.043305162683177e-06
                                                    rotation 0.5773502691896258 -0.5773502691896258 -0.5773502691896258 2.0944
                                                    children [
                                                      DEF LEFT_FINGER_SLIDER SliderJoint {
                                                        jointParameters JointParameters {
                                                          position 0.03999999998627568
                                                          axis -1 0 0
                                                        }
                                                        device [
                                                          LinearMotor {
                                                            name "finger motor::left"
                                                            minPosition -1.8020568378662854e-10
                                                            maxPosition 0.1
                                                          }
                                                        ]
                                                        endPoint DEF LEFT_FINGER Solid {
                                                          translation -0.06199999998627568 0 -0.02
                                                          children [
                                                            Group {
                                                              children [
                                                                Pose {
                                                                  translation 0 0.0015 -0.003
                                                                  children [
                                                                    Shape {
                                                                      appearance DEF METAL_APPEARANCE PBRAppearance {
                                                                        baseColorMap ImageTexture {
                                                                          url [
                                                                            "https://raw.githubusercontent.com/cyberbotics/webots/R2025a/projects/default/worlds/textures/metal.jpg"
                                                                          ]
                                                                        }
                                                                        roughness 0.2
                                                                      }
                                                                      geometry Box {
                                                                        size 0.018 0.031 0.036
                                                                      }
                                                                    }
                                                                  ]
                                                                }
                                                                DEF LEFT_FINGER_TRANSFORM Pose {
                                                                  translation 0.0015 -0.006 -0.069
                                                                  children [
                                                                    Shape {
                                                                      appearance DEF BLACK_APPEARANCE PBRAppearance {
                                                                        baseColor 0.0705882 0.0705882 0.0705882
                                                                        roughness 0.4
                                                                        metalness 0
                                                                      }
                                                                      geometry Box {
                                                                        size 0.015 0.035 0.095
                                                                      }
                                                                    }
                                                                  ]
                                                                }
                                                              ]
                                                            }
                                                          ]
                                                          name "left finger"
                                                          boundingObject USE LEFT_FINGER_TRANSFORM
                                                          physics DEF LEFT_FINGER_PHYSICS Physics {
                                                          }
                                                          linearVelocity -5.131097832397243e-07 3.172578858590291e-05 -1.0367999384133648e-05
                                                          angularVelocity -8.362082307320135e-05 3.6385823810702366e-07 1.1595782559990335e-05
                                                        }
                                                      }
                                                      DEF RIGHT_FINGER_SLIDER SliderJoint {
                                                        jointParameters JointParameters {
                                                          position 0.04000000001575886
                                                          axis 1 0 0
                                                        }
                                                        device [
                                                          LinearMotor {
                                                            name "finger motor::right"
                                                            minPosition -1.8020568378662854e-10
                                                            maxPosition 0.1
                                                          }
                                                        ]
                                                        endPoint DEF RIGHT_FINGER Solid {
                                                          translation 0.06200000001575886 0 -0.02
                                                          children [
                                                            Group {
                                                              children [
                                                                Pose {
                                                                  translation 0 0.0015 -0.003
                                                                  children [
                                                                    Shape {
                                                                      appearance USE METAL_APPEARANCE
                                                                      geometry Box {
                                                                        size 0.018 0.031 0.036
                                                                      }
                                                                    }
                                                                  ]
                                                                }
                                                                DEF RIGHT_FINGER_TRANSFORM Pose {
                                                                  translation -0.0015 -0.006 -0.069
                                                                  children [
                                                                    Shape {
                                                                      appearance USE BLACK_APPEARANCE
                                                                      geometry Box {
                                                                        size 0.015 0.035 0.095
                                                                      }
                                                                    }
                                                                  ]
                                                                }
                                                              ]
                                                            }
                                                          ]
                                                          name "right finger"
                                                          boundingObject USE RIGHT_FINGER_TRANSFORM
                                                          physics USE LEFT_FINGER_PHYSICS
                                                          linearVelocity 8.89823999184093e-07 3.172587571932668e-05 -2.505975582240053e-07
                                                          angularVelocity -8.362054428183027e-05 3.6388336948449267e-07 1.1595782106856656e-05
                                                        }
                                                      }
                                                      Pose {
                                                        translation 0 -0.126 0.135
                                                        children [
                                                          Group {
                                                            children [
                                                              Pose {
                                                                translation 0 0.1478 -0.154
                                                                children [
                                                                  DEF UPPER_BOX Shape {
                                                                    appearance USE BLACK_APPEARANCE
                                                                    geometry Box {
                                                                      size 0.315 0.01 0.043419
                                                                    }
                                                                  }
                                                                ]
                                                              }
                                                              Pose {
                                                                translation 0 0.1072 -0.154
                                                                children [
                                                                  USE UPPER_BOX
                                                                ]
                                                              }
                                                              Pose {
                                                                translation -0.155 0.1275 -0.154
                                                                children [
                                                                  DEF LEFT_BOX Shape {
                                                                    appearance USE BLACK_APPEARANCE
                                                                    geometry Box {
                                                                      size 0.007 0.05 0.042227
                                                                    }
                                                                  }
                                                                ]
                                                              }
                                                              Pose {
                                                                translation 0.155 0.1275 -0.154
                                                                children [
                                                                  USE LEFT_BOX
                                                                ]
                                                              }
                                                              Pose {
                                                                translation 0 0.126 -0.158
                                                                children [
                                                                  DEF CENTER_BOX Shape {
                                                                    appearance USE BLACK_APPEARANCE
                                                                    geometry Box {
                                                                      size 0.027 0.0341 0.035
                                                                    }
                                                                  }
                                                                ]
                                                              }
                                                              Pose {
                                                                translation 0 0.132 -0.154
                                                                rotation -0.5773489358556708 -0.5773509358554485 0.5773509358554485 2.094397
                                                                children [
                                                                  DEF UPPER_CYLINDER Shape {
                                                                    appearance USE METAL_APPEARANCE
                                                                    geometry Cylinder {
                                                                      height 0.3
                                                                      radius 0.00225
                                                                    }
                                                                  }
                                                                ]
                                                              }
                                                              Pose {
                                                                translation 0 0.118 -0.154
                                                                rotation -0.5773489358556708 -0.5773509358554485 0.5773509358554485 2.094397
                                                                children [
                                                                  Shape {
                                                                    appearance USE METAL_APPEARANCE
                                                                    geometry Cylinder {
                                                                      height 0.3
                                                                      radius 0.00125
                                                                    }
                                                                  }
                                                                ]
                                                              }
                                                              Pose {
                                                                translation -0.041 0.155 -0.148
                                                                children [
                                                                  Shape {
                                                                    appearance USE BLACK_APPEARANCE
                                                                    geometry Box {
                                                                      size 0.0141907 0.006 0.04
                                                                    }
                                                                  }
                                                                ]
                                                              }
                                                              Pose {
                                                                translation -0.036 0.145 -0.116
                                                                children [
                                                                  Shape {
                                                                    appearance USE METAL_APPEARANCE
                                                                    geometry Box {
                                                                      size 0.027 0.03 0.03
                                                                    }
                                                                  }
                                                                ]
                                                              }
                                                              Pose {
                                                                translation 0.041 0.155 -0.148
                                                                children [
                                                                  Shape {
                                                                    appearance USE BLACK_APPEARANCE
                                                                    geometry Box {
                                                                      size 0.0141907 0.006 0.04
                                                                    }
                                                                  }
                                                                ]
                                                              }
                                                              Pose {
                                                                translation 0.036 0.145 -0.116
                                                                children [
                                                                  Shape {
                                                                    appearance USE METAL_APPEARANCE
                                                                    geometry Box {
                                                                      size 0.027 0.03 0.03
                                                                    }
                                                                  }
                                                                ]
                                                              }
                                                            ]
                                                          }
                                                        ]
                                                      }
                                                    ]
                                                    boundingObject Pose {
                                                      translation 0 0.0015 -0.019
                                                      children [
                                                        Shape {
                                                          appearance USE METAL_APPEARANCE
                                                          geometry Box {
                                                            size 0.315 0.05 0.045
                                                          }
                                                        }
                                                      ]
                                                    }
                                                    physics DEF LIFT_PHYSICS Physics {
                                                    }
                                                    linearVelocity 1.9109121964433378e-07 3.1543808351744156e-05 -5.279198384916119e-06
                                                    angularVelocity -8.362068603991126e-05 3.6370951570260563e-07 1.1595869109270246e-05
                                                  }
                                                }
                                                Pose {
                                                  translation -0.135 0 -0.126
                                                  rotation 0.5773502691896258 -0.5773502691896258 -0.5773502691896258 2.094395
                                                  children [
                                                    DEF BASE_SHAPE_GROUP Group {
                                                      children [
                                                        Pose {
                                                          translation 0 0.176 -0.154
                                                          children [
                                                            DEF UPPER_BOX Shape {
                                                              appearance USE BLACK_APPEARANCE
                                                              geometry Box {
                                                                size 0.141092 0.0170038 0.043419
                                                              }
                                                            }
                                                          ]
                                                        }
                                                        Pose {
                                                          translation 0 0.075 -0.154
                                                          children [
                                                            USE UPPER_BOX
                                                          ]
                                                        }
                                                        Pose {
                                                          translation -0.06 0.126 -0.158
                                                          children [
                                                            DEF LEFT_BOX Shape {
                                                              appearance USE BLACK_APPEARANCE
                                                              geometry Box {
                                                                size 0.02 0.0875 0.035
                                                              }
                                                            }
                                                          ]
                                                        }
                                                        Pose {
                                                          translation 0.06 0.126 -0.158
                                                          children [
                                                            USE LEFT_BOX
                                                          ]
                                                        }
                                                        Pose {
                                                          translation 0 0.126 -0.158
                                                          children [
                                                            DEF CENTER_BOX Shape {
                                                              appearance USE BLACK_APPEARANCE
                                                              geometry Box {
                                                                size 0.044 0.1 0.0315
                                                              }
                                                            }
                                                          ]
                                                        }
                                                        Pose {
                                                          translation -0.037 0.126 -0.158
                                                          rotation 1 0 0 -1.570796
                                                          children [
                                                            DEF LEFT_CYLINDER Shape {
                                                              appearance USE METAL_APPEARANCE
                                                              geometry Cylinder {
                                                                height 0.1
                                                                radius 0.003
                                                              }
                                                            }
                                                          ]
                                                        }
                                                        Pose {
                                                          translation 0.037 0.126 -0.158
                                                          rotation 1 0 0 -1.570796
                                                          children [
                                                            USE LEFT_CYLINDER
                                                          ]
                                                        }
                                                      ]
                                                    }
                                                  ]
                                                }
                                              ]
                                              name "Pioneer3 gripper"
                                              model "Pioneer3 gripper"
                                              boundingObject Pose {
                                                translation 0.019 0 0
                                                children [
                                                  Box {
                                                    size 0.043 0.141 0.117
                                                  }
                                                ]
                                              }
                                              physics DEF BASE_PHYSICS Physics {
                                              }
                                            }
                                          ]
                                        }
                                      ]
                                      name "wrist_3_link"
                                      boundingObject Group {
                                        children [
                                          Pose {
                                            translation 0 0.07 0
                                            rotation 1 0 0 -1.57079632679
                                            children [
                                              Cylinder {
                                                height 0.048
                                                radius 0.038
                                              }
                                            ]
                                          }
                                          Pose {
                                            translation 0 0.09 0
                                            rotation 1 0 0 -1.57079632679
                                            children [
                                              Cylinder {
                                                height 0.018
                                                radius 0.032
                                              }
                                            ]
                                          }
                                        ]
                                      }
                                      physics Physics {
                                        density -1
                                        mass 0.365
                                        centerOfMass [
                                          0 0.071 0
                                        ]
                                      }
                                      linearVelocity 1.906620638840079e-07 3.077509283573722e-05 -4.907197143942917e-06
                                      angularVelocity -8.362141991680734e-05 3.6086766014954823e-07 1.1597488067301085e-05
                                    }
                                  }
                                ]
                                name "wrist_2_link"
                                boundingObject Group {
                                  children [
                                    Pose {
                                      translation 0 -0.001 0.0995
                                      rotation 1 0 0 -1.57079632679
                                      children [
                                        Cylinder {
                                          height 0.108
                                          radius 0.04
                                        }
                                      ]
                                    }
                                    Pose {
                                      translation 0 -0.001 0.0676
                                      children [
                                        Cylinder {
                                          height 0.043
                                          radius 0.038
                                        }
                                      ]
                                    }
                                  ]
                                }
                                physics Physics {
                                  density -1
                                  mass 1.3
                                  centerOfMass [
                                    0 0 0.1
                                  ]
                                }
                                linearVelocity 1.9097688203168321e-07 2.96704654557437e-05 -4.696082568667427e-06
                                angularVelocity -6.436098015902492e-05 3.377631150827478e-07 1.160857943355518e-05
                              }
                            }
                          ]
                          name "wrist_1_link"
                          boundingObject Group {
                            children [
                              Pose {
                                translation 0 0.089 0
                                rotation 1 0 0 -1.57079632679
                                children [
                                  Cylinder {
                                    height 0.086
                                    radius 0.038
                                  }
                                ]
                              }
                              Pose {
                                translation 0 0.126 0
                                children [
                                  Cylinder {
                                    height 0.112
                                    radius 0.038
                                  }
                                ]
                              }
                            ]
                          }
                          physics Physics {
                            density -1
                            mass 1.37
                            centerOfMass [
                              0 0.127 0
                            ]
                          }
                          linearVelocity 1.5776172309431768e-07 2.3375416392872245e-05 -4.401335372374719e-06
                          angularVelocity -6.437674843055388e-05 3.146778609328805e-07 -7.64287353166935e-06
                        }
                      }
                    ]
                    name "forearm_link"
                    boundingObject Group {
                      children [
                        Pose {
                          translation 0 0 0.207
                          children [
                            Cylinder {
                              height 0.36
                              radius 0.038
                            }
                          ]
                        }
                        Pose {
                          translation 0 -0.001 0.39
                          rotation 1 0 0 -1.57079632679
                          children [
                            Cylinder {
                              height 0.109
                              radius 0.039
                            }
                          ]
                        }
                        Pose {
                          translation 0 0.06 0
                          rotation 1 0 0 1.57079632679
                          children [
                            Capsule {
                              height 0.05
                              radius 0.058
                              subdivision 16
                            }
                          ]
                        }
                        Pose {
                          translation 0 0 0.07
                          children [
                            Capsule {
                              height 0.1
                              radius 0.04
                              subdivision 16
                            }
                          ]
                        }
                      ]
                    }
                    physics Physics {
                      density -1
                      mass 2.846
                      centerOfMass [
                        0 0 0.15
                      ]
                    }
                    linearVelocity 1.008627059689313e-07 8.98753242277094e-06 -3.939317337705954e-06
                    angularVelocity -6.423915781488417e-05 2.3820345951992558e-07 -7.607402236319126e-06
                  }
                }
              ]
              name "upper_arm_link"
              boundingObject Group {
                children [
                  Pose {
                    translation 0 0 0.22
                    children [
                      Cylinder {
                        height 0.407
                        radius 0.059
                      }
                    ]
                  }
                  Pose {
                    rotation 1 0 0 -1.57079632679
                    children [
                      Cylinder {
                        height 0.133
                        radius 0.059
                      }
                    ]
                  }
                  Pose {
                    translation 0 -0.005 0.424
                    rotation 1 0 0 -1.57079632679
                    children [
                      Cylinder {
                        height 0.149
                        radius 0.059
                      }
                    ]
                  }
                ]
              }
              physics Physics {
                density -1
                mass 8.058
                centerOfMass [
                  0 0 0.2125
                ]
              }
              linearVelocity 3.1809474398218865e-08 -1.4471069017158231e-06 -3.272581202061142e-06
              angularVelocity -1.3494806859622647e-07 1.6143273817595888e-07 -7.57348592549986e-06
            }
          }
        ]
        name "shoulder_link"
        boundingObject Group {
          children [
            Pose {
              children [
                Cylinder {
                  height 0.135
                  radius 0.059
                }
              ]
            }
            Pose {
              translation 0 0.03 0
              rotation 1 0 0 -1.57079632679
              children [
                Cylinder {
                  height 0.093
                  radius 0.059
                }
              ]
            }
          ]
        }
        physics Physics {
          density -1
          mass 3.761
          centerOfMass [
            0 -0.02561 0.00193
          ]
        }
        linearVelocity -9.052273137873865e-10 -2.1700932278771148e-08 -1.7987715188378605e-06
        angularVelocity 1.9260105399481097e-07 1.7583385143121378e-07 -7.567821652082928e-06
      }
    }
  ]
  name "UR5e"
  model "UR5e"
  boundingObject Pose {
    translation 0 0 0.05
    children [
      Cylinder {
        height 0.1
        radius 0.076
      }
    ]
  }
  controller "arm_controller"
  selfCollision TRUE
}
